Workbook

Sheet REKAP HUTANG
B1: PT. GEMA TEKNIK PERKASA
B2: REKAP DATA HUTANG
B3: TAHUN 2022
B5: No | C5: Periode | D5: Keterangan
D6: Jasa | E6: Anchor | F6: Material | G6: Sewa Alat | H6: Total
B8: 1 | C8: JANUARI | D8: ='INV JANUARI'!D43 -> 33810000 | E8: ='INV JANUARI'!E43 -> 9750000 | F8: ='INV JANUARI'!F43 -> 2417715416 | G8: ='INV JANUARI'!G43 -> 14600000 | H8: =SUM(D8:G8) -> 2475875416
B9: 2 | C9: FEBRUARI | D9: ='INV FEBRUARI'!D34 -> 12000000 | E9: ='INV FEBRUARI'!E34 -> 274285000 | F9: ='INV FEBRUARI'!F34 -> 1.182032e+09 | G9: ='INV FEBRUARI'!G34 -> 0 | H9: =SUM(D9:G9) -> 1.468317e+09
B10: 3 | C10: MARET | D10: ='INV MARET'!D30 -> 71830000 | E10: ='INV MARET'!E30 -> 0 | F10: ='INV MARET'!F30 -> 157800000 | G10: ='INV MARET'!G30 -> 0 | H10: =SUM(D10:G10) -> 229630000
B11: 4 | C11: APRIL | D11: ='INV APRIL'!D28 -> 25000000 | E11: ='INV APRIL'!E28 -> 0 | F11: ='INV APRIL'!F28 -> 2385953740 | G11: ='INV APRIL'!G28 -> 0 | H11: =SUM(D11:G11) -> 2410953740
B12: 5 | C12: MEI | D12: ='INV MEI'!D19 -> 0 | E12: ='INV MEI'!E19 -> 0 | F12: ='INV MEI'!F19 -> 213920500 | G12: ='INV MEI'!G19 -> 0 | H12: =SUM(D12:G12) -> 213920500
B13: 6 | C13: JUNI | D13: ='INV JUNI'!D21 -> 3250000 | E13: ='INV JUNI'!E21 -> 0 | F13: ='INV JUNI'!F21 -> 412206650 | G13: ='INV JUNI'!G21 -> 0 | H13: =SUM(D13:G13) -> 415456650
B14: 7 | C14: JULI | D14: ='INV JULI'!D21 -> 2330000 | E14: ='INV JULI'!E21 -> 0 | F14: ='INV JULI'!F21 -> 924958315 | G14: ='INV JULI'!G21 -> 0 | H14: =SUM(D14:G14) -> 927288315
B15: 8 | C15: AGUSTUS | D15: ='INV AGUSTUS'!D19 -> 0 | E15: ='INV AGUSTUS'!E19 -> 0 | F15: ='INV AGUSTUS'!F19 -> 777944300 | G15: ='INV AGUSTUS'!G19 -> 0 | H15: =SUM(D15:G15) -> 777944300
B16: 9 | C16: SEPTEMBER | D16: ='INV SEPTEMBER'!D19 -> 145600000 | E16: ='INV SEPTEMBER'!E19 -> 52046500 | F16: ='INV SEPTEMBER'!F19 -> 137618875 | G16: ='INV SEPTEMBER'!G19 -> 0 | H16: =SUM(D16:G16) -> 335265375
B17: 10 | C17: OKTOBER | D17: ='INV OKTOBER'!D28 -> 1200000 | E17: ='INV OKTOBER'!E28 -> 0 | F17: ='INV OKTOBER'!F28 -> 527452500 | G17: ='INV OKTOBER'!G28 -> 0 | H17: =SUM(D17:G17) -> 528652500
B18: 11 | C18: NOPEMBER | D18: ='INV NOVEMBER'!D29 -> 47936406 | E18: ='INV NOVEMBER'!E29 -> 32985000 | F18: ='INV NOVEMBER'!F29 -> 8.7635547e+08 | G18: ='INV NOVEMBER'!G29 -> 0 | H18: =SUM(D18:G18) -> 957276875
B19: 12 | C19: DESEMBER | D19: ='INV DESEMBER'!D38 -> 91900000 | E19: ='INV DESEMBER'!E38 -> 12000000 | F19: ='INV DESEMBER'!F38 -> 3178322500 | G19: ='INV DESEMBER'!G38 -> 0 | H19: =SUM(D19:G19) -> 3282222500
C20: TOTAL | D20: =SUM(D8:D19) -> 4.3485641e+08 | E20: =SUM(E8:E19) -> 381066500 | F20: =SUM(F8:F19) -> 1.319228e+10 | G20: =SUM(G8:G19) -> 14600000 | H20: =SUM(H8:H19) -> 1.4022803e+10

Sheet INV JANUARI
A1: Kewajiban GMT Januari 2025
A3: PPN
A4: Tanggal | B4: No. Invoice | C4: Suplier | D4: Keterangan | L4: Tgl Pembayaran | M4: Beban Admin | N4: Nilai Pembayaran | P4: Saldo AP
D5: Jasa | E5: Anchor | F5: Material | G5: Sewa Alat | H5: Total | I5: PPN | J5: Grand Total
A6: 45659 | B6: 3249001217 | C6: PT. Indoporlen | F6: 85140000 | H6: =SUM(D6:G6) -> 85140000 | I6: =H6*0.11 -> 9365400 | J6: =H6+I6 -> 94505400 | L6: 45699 | M6: 0 | N6: =J6-M6 -> 94505400 | P6: =J6-M6-N6 -> 0
A7: 45659 | B7: 3249001216 | C7: PT. Indoporlen | F7: 1265660000 | H7: =SUM(D7:G7) -> 1265660000 | I7: =H7*0.11 -> 139222600 | J7: =H7+I7 -> 1404882600 | L7: 45699 | N7: =J7-M7 -> 1404882600 | P7: =J7-M7-N7 -> 0
A8: 45659 | B8: 3249001218 | C8: PT. Indoporlen | F8: 121880000 | H8: =SUM(D8:G8) -> 121880000 | I8: =H8*0.11 -> 13406800 | J8: =H8+I8 -> 135286800 | L8: 45699 | N8: =J8-M8 -> 135286800 | P8: =J8-M8-N8 -> 0
A9: 45659 | B9: 3249001192 | C9: PT. Indoporlen | F9: 690000 | H9: =SUM(D9:G9) -> 690000 | I9: =H9*0.11 -> 75900 | J9: =H9+I9 -> 765900 | L9: 45699 | N9: =J9-M9 -> 765900 | P9: =J9-M9-N9 -> 0
A10: 45659 | B10: 3249001221 | C10: PT. Indoporlen | F10: 6900000 | H10: =SUM(D10:G10) -> 6900000 | I10: =H10*0.11 -> 759000 | J10: =H10+I10 -> 7659000 | L10: 45699 | N10: =J10-M10 -> 7659000 | P10: =J10-M10-N10 -> 0
A11: 45659 | B11: 3249001220 | C11: PT. Indoporlen | F11: 6210000 | H11: =SUM(D11:G11) -> 6210000 | I11: =H11*0.11 -> 683100 | J11: =H11+I11 -> 6893100 | L11: 45699 | N11: =J11-M11 -> 6893100 | P11: =J11-M11-N11 -> 0
A12: 45659 | B12: 3249001219 | C12: PT. Indoporlen | F12: 9900000 | H12: =SUM(D12:G12) -> 9900000 | I12: =H12*0.11 -> 1089000 | J12: =H12+I12 -> 10989000 | L12: 45699 | N12: =J12-M12 -> 10989000 | P12: =J12-M12-N12 -> 0
A13: 45666 | B13: 071/GTP/AMS/2024 | C13: PT. Allied Makmur Service | F13: 359800000 | H13: =SUM(D13:G13) -> 359800000 | I13: =H13*0.11 -> 39578000 | J13: =H13+I13 -> 399378000 | L13: 45699 | N13: =J13-M13 -> 399378000 | P13: =J13-M13-N13 -> 0 | Q13: =P13+P14+P15 -> 0
A14: 45666 | B14: 069/GTP/AMS/2024 | C14: PT. Allied Makmur Service | F14: 99000000 | H14: =SUM(D14:G14) -> 99000000 | I14: =H14*0.11 -> 10890000 | J14: =H14+I14 -> 109890000 | L14: 45699 | N14: =J14-M14 -> 109890000 | P14: =J14-M14-N14 -> 0
A15: 45666 | B15: 066/GTP/AMS/2024 | C15: PT. Allied Makmur Service | F15: 233000000 | H15: =SUM(D15:G15) -> 233000000 | I15: =H15*0.11 -> 25630000 | J15: =H15+I15 -> 258630000 | L15: 45699 | N15: =J15-M15 -> 258630000 | P15: =J15-M15-N15 -> 0
A16: 45666 | B16: 503/INV-MES/I/25 | C16: PT. Mega Eka Satya | D16: =2694375-894375 -> 1800000 | F16: =15268125-5068125 -> 10200000 | H16: =SUM(D16:G16) -> 12000000 | I16: =H16*0.11 -> 1320000 | J16: =H16+I16 -> 13320000 | L16: 45680 | N16: =J16-M16 -> 13320000 | P16: =J16-M16-N16 -> 0
A17: 45666 | B17: 153 | C17: Suwarso | D17: 1800000 | H17: =SUM(D17:G17) -> 1800000 | I17: 0 | J17: =H17+I17 -> 1800000 | L17: 45671 | M17: 0 | N17: =J17-M17 -> 1800000 | P17: =J17-M17-N17 -> 0
A18: 45667 | B18: SI-2412043 | C18: PT. Caprefindo | F18: 7150000 | H18: =SUM(D18:G18) -> 7150000 | I18: =H18*0.11 -> 786500 | J18: =H18+I18 -> 7936500 | L18: 45699 | M18: 0 | N18: =J18-M18 -> 7936500 | P18: =J18-M18-N18 -> 0
A19: 45665 | B19: 004/CMB/I/2025 | C19: PT. Cahaya Mega Buana | F19: 1400000 | H19: =SUM(D19:G19) -> 1400000 | I19: =H19*0.11 -> 154000 | J19: =H19+I19 -> 1554000 | L19: 45665 | M19: 0 | N19: =J19-M19 -> 1554000 | P19: =J19-M19-N19 -> 0
A20: 45667 | B20: INV/25/I/001 | C20: CV. Bintang Utama | F20: 9100000 | H20: =SUM(D20:G20) -> 9100000 | I20: 0 | J20: =H20+I20 -> 9100000 | L20: 45667 | M20: 0 | N20: =J20-M20 -> 9100000 | P20: =J20-M20-N20 -> 0
A21: 45668 | C21: Sarana Karya Mandiri | D21: 1660000 | H21: =SUM(D21:G21) -> 1660000 | I21: 0 | J21: =H21+I21 -> 1660000 | L21: 45671 | M21: 0 | N21: =J21-M21 -> 1660000 | P21: =J21-M21-N21 -> 0
A22: 45672 | B22: 04/INV/IP/I/2025 | C22: PT. Indoporlen | F22: 21470000 | H22: =SUM(D22:G22) -> 21470000 | I22: =H22*0.11 -> 2361700 | J22: =H22+I22 -> 23831700 | L22: 45716 | M22: 0 | N22: =J22-M22 -> 23831700 | P22: =J22-M22-N22 -> 0
A23: 45673 | B23: 026/Inv/250115-026 | C23: PT. Aurora Sheet Metal | D23: 650000 | H23: =SUM(D23:G23) -> 650000 | I23: 0 | J23: =H23+I23 -> 650000 | L23: 45673 | M23: 0 | N23: =J23-M23 -> 650000 | P23: =J23-M23-N23 -> 0
A24: 45673 | B24: 154 | C24: Suwarso | D24: 3400000 | H24: =SUM(D24:G24) -> 3400000 | I24: 0 | J24: =H24+I24 -> 3400000 | L24: 45699 | N24: =J24-M24 -> 3400000 | P24: =J24-M24-N24 -> 0
A25: 45674 | B25: 3259000012 | C25: PT. Indoporlen | F25: =9120000+13870000 -> 22990000 | H25: =SUM(D25:G25) -> 22990000 | I25: =H25*0.11 -> 2528900 | J25: =H25+I25 -> 25518900 | L25: 45716 | N25: =J25-M25 -> 25518900 | P25: =J25-M25-N25 -> 0
A26: 45677 | B26: 250100245 | C26: PT. Makmur Meta Graha Dinamika | F26: 28875000 | H26: =SUM(D26:G26) -> 28875000 | I26: =H26*0.11 -> 3176250 | J26: =H26+I26 -> 32051250 | N26: 0 | P26: =J26-M26-N26 -> 32051250
A27: 45677 | B27: 234/INV/XII/2024 | C27: PT. Max Rent Indonesia | G27: 14600000 | H27: =SUM(D27:G27) -> 14600000 | I27: =H27*0.11 -> 1606000 | J27: =H27+I27 -> 16206000 | L27: 45657 | N27: =J27-M27 -> 16206000 | P27: =J27-M27-N27 -> 0
A28: 45680 | B28: 28/INV/IP/I/2025 | C28: PT. Indoporlen | F28: 12650000 | H28: =SUM(D28:G28) -> 12650000 | I28: =H28*0.11 -> 1391500 | J28: =H28+I28 -> 14041500 | L28: 45716 | N28: =J28-M28 -> 14041500 | P28: =J28-M28-N28 -> 0
A29: 45680 | B29: 30/INV/IP/I/2025 | C29: PT. Indoporlen | F29: 8071250 | H29: =SUM(D29:G29) -> 8071250 | I29: =H29*0.11 -> 887837.5 | J29: =H29+I29 -> 8959087.5 | L29: 45716 | N29: =J29-M29 -> 8959087.5 | P29: =J29-M29-N29 -> 0
A30: 45680 | B30: 34/INV/IP/I/2025 | C30: PT. Indoporlen | F30: 11595833 | H30: =SUM(D30:G30) -> 11595833 | I30: =H30*0.11 -> 1275541.6 | J30: =H30+I30 -> 12871375 | L30: 45716 | N30: =J30-M30 -> 12871375 | P30: =J30-M30-N30 -> 0
A31: 45680 | B31: 29/INV/IP/I/2025 | C31: PT. Indoporlen | F31: 5573333 | H31: =SUM(D31:G31) -> 5573333 | I31: =H31*0.11 -> 613066.63 | J31: =H31+I31 -> 6186399.6 | L31: 45716 | N31: =J31-M31 -> 6186399.6 | P31: =J31-M31-N31 -> 0
A32: 45685 | B32: 503P/INV-MES/I/25 | C32: PT. Mega Eka Satya | D32: =6286875-2086875 -> 4200000 | F32: =35625625-11825625 -> 23800000 | H32: =SUM(D32:G32) -> 28000000 | I32: =H32*0.11 -> 3080000 | J32: =H32+I32 -> 31080000 | L32: 45716 | N32: =J32-M32 -> 31080000 | P32: =J32-M32-N32 -> 0
A33: 45685 | B33: SI-2501012 | C33: PT. Caprefindo | F33: 26250000 | H33: =SUM(D33:G33) -> 26250000 | I33: =H33*0.11 -> 2887500 | J33: =H33+I33 -> 29137500 | L33: 45699 | N33: =J33-M33 -> 29137500 | P33: =J33-M33-N33 -> 0
A34: 45685 | B34: 003MC/INV/DMP-GTP/I/25 | C34: PT. Dwitama Metal Presisi | E34: 1350000 | H34: =SUM(D34:G34) -> 1350000 | I34: =H34*0.11 -> 148500 | J34: =H34+I34 -> 1498500 | L34: 45716 | N34: =J34-M34 -> 1498500 | P34: =J34-M34-N34 -> 0
A35: 45680 | C35: Sarana Karya Mandiri | D35: 20300000 | H35: =SUM(D35:G35) -> 20300000 | I35: 0 | J35: =H35+I35 -> 20300000 | L35: 45680 | N35: =J35-M35 -> 20300000 | P35: =J35-M35-N35 -> 0
A36: 45670 | B36: 34/J/I/25 | C36: PT. Jaya Refractorindo Utama | F36: 40410000 | H36: =SUM(D36:G36) -> 40410000 | I36: =H36*0.11 -> 4445100 | J36: =H36+I36 -> 44855100 | L36: 45670 | N36: =J36-M36 -> 44855100 | P36: =J36-M36-N36 -> 0
A37: 45687 | C37: GW Coin Rubber | E37: 8400000 | H37: =SUM(D37:G37) -> 8400000 | I37: 0 | J37: =H37+I37 -> 8400000 | L37: 45687 | N37: =J37-M37 -> 8400000 | P37: =J37-M37-N37 -> 0
H38: =SUM(D38:G38) -> 0 | I38: =H38*0.11 -> 0 | J38: =H38+I38 -> 0 | N38: 0 | P38: =J38-M38-N38 -> 0
H39: =SUM(D39:G39) -> 0 | I39: =H39*0.11 -> 0 | J39: =H39+I39 -> 0 | N39: 0 | P39: =J39-M39-N39 -> 0
H40: =SUM(D40:G40) -> 0 | I40: =H40*0.11 -> 0 | J40: =H40+I40 -> 0 | N40: 0 | P40: =J40-M40-N40 -> 0
H41: =SUM(D41:G41) -> 0 | I41: 0 | J41: =H41+I41 -> 0 | N41: 0 | P41: =J41-M41-N41 -> 0
...

Sheet INV FEBRUARI
A1: Kewajiban GMT Februari 2025
A4: PPN
A5: Tanggal | B5: No. Invoice | C5: Supplier | D5: Keterangan | L5: Tgl Pembayaran | M5: Beban Admin | N5: Nilai Pembayaran | P5: Saldo AP
D6: Jasa | E6: Anchor | F6: Material | G6: Sewa Alat | H6: Total | I6: PPN | J6: Grand Total
A7: 45701 | B7: 0179/INV-MULA/II-25 | C7: PT. Mitra Utama Lestari Abadi | F7: 25500000 | H7: =SUM(D7:G7) -> 25500000 | I7: =H7*0.11 -> 2805000 | J7: =H7+I7 -> 28305000 | L7: 45699 | M7: 0 | N7: =J7-M7 -> 28305000 | P7: =J7-M7-N7 -> 0
A8: 45694 | B8: 18/PO/GMT/II/2025 | C8: CV. Putra Indra Boga | E8: 38060000 | H8: =SUM(D8:G8) -> 38060000 | I8: =H8*0.11 -> 4186600 | J8: =H8+I8 -> 42246600 | L8: 45694 | M8: 0 | N8: =J8-M8 -> 42246600 | P8: =J8-M8-N8 -> 0
A9: 45694 | C9: CV. Karya Teknik Mesin Kardim | E9: 13500000 | H9: =SUM(D9:G9) -> 13500000 | I9: 0 | J9: =H9+I9 -> 13500000 | L9: 45694 | N9: =J9-M9 -> 13500000 | P9: =J9-M9-N9 -> 0
A10: 45695 | C10: Naharudin | F10: 1200000 | H10: =SUM(D10:G10) -> 1200000 | I10: 0 | J10: =H10+I10 -> 1200000 | L10: 45695 | N10: =J10-M10 -> 1200000 | P10: =J10-M10-N10 -> 0
A11: 45695 | B11: 19/PO/GMT/II/2025 | C11: CV. Putra Indra Boga | E11: 36500000 | H11: =SUM(D11:G11) -> 36500000 | I11: =H11*0.11 -> 4015000 | J11: =H11+I11 -> 40515000 | L11: 45695 | N11: =J11-M11 -> 40515000 | P11: =J11-M11-N11 -> 0
A12: 45699 | B12: 24/PO/GMT/II/2025 | C12: CV. Putra Indra Boga | E12: 72425000 | H12: =SUM(D12:G12) -> 72425000 | I12: =H12*0.11 -> 7966750 | J12: =H12+I12 -> 80391750 | L12: 45699 | N12: =J12-M12 -> 80391750 | P12: =J12-M12-N12 -> 0
A13: 45693 | B13: 2520053 | C13: PT. Shinagawa Refratech Perkasa | F13: 7650000 | H13: =SUM(D13:G13) -> 7650000 | I13: =H13*0.11 -> 841500 | J13: =H13+I13 -> 8491500 | L13: 45716 | N13: =J13-M13 -> 8491500 | P13: =J13-M13-N13 -> 0
A14: 45692 | B14: WIP/0119/T/II/2025 | C14: PT. Willich Isolasi Pratama | F14: 80000000 | H14: =SUM(D14:G14) -> 80000000 | I14: =H14*0.11 -> 8800000 | J14: =H14+I14 -> 88800000 | L14: 45692 | N14: =J14-M14 -> 88800000 | P14: =J14-M14-N14 -> 0
A15: 45702 | B15: 20/GMT/PO/II/2025 | C15: CV. Putra Indra Boga | F15: 27500000 | H15: =SUM(D15:G15) -> 27500000 | I15: =H15*0.11 -> 3025000 | J15: =H15+I15 -> 30525000 | L15: 45702 | N15: =J15-M15 -> 30525000 | P15: =J15-M15-N15 -> 0
A16: 45705 | B16: 016-02-25-GTP | C16: PT. Akurasi Presisi Indonesia | D16: 12000000 | H16: =SUM(D16:G16) -> 12000000 | I16: =H16*0.11 -> 1320000 | J16: =H16+I16 -> 13320000 | L16: 45705 | N16: =J16-M16 -> 13320000 | P16: =J16-M16-N16 -> 0
A17: 45707 | B17: 0084/BAT/I/2025/AGS | C17: PT. Benteng Api Technic tbk | F17: 850990000 | H17: =SUM(D17:G17) -> 850990000 | I17: =H17*0.11 -> 93608900 | J17: =H17+I17 -> 944598900 | N17: 0 | P17: =J17-M17-N17 -> 944598900
A18: 45706 | B18: 10362 | C18: CV. Putra Indra Boga | E18: 22500000 | H18: =SUM(D18:G18) -> 22500000 | I18: =H18*0.11 -> 2475000 | J18: =H18+I18 -> 24975000 | L18: 45706 | N18: =J18-M18 -> 24975000 | P18: =J18-M18-N18 -> 0
A19: 45706 | B19: 013/INV-ASM/II/2025 | C19: CV. Aurora Sheet Metal | E19: 46800000 | H19: =SUM(D19:G19) -> 46800000 | I19: =H19*0.11 -> 5148000 | J19: =H19+I19 -> 51948000 | L19: 45706 | N19: =J19-M19 -> 51948000 | P19: =J19-M19-N19 -> 0
A20: 45707 | B20: 008884 | C20: PT. Diamond Jack Indonesia | F20: =270000/1.11 -> 243243.24 | H20: =SUM(D20:G20) -> 243243.24 | I20: =H20*0.11 -> 26756.757 | J20: =H20+I20 -> 270000 | L20: 45707 | N20: =J20-M20 -> 270000 | P20: =J20-M20-N20 -> 0
A21: 45707 | B21: 27/GMT/PO/II/2025 | C21: CV. Putra Indra Boga | E21: 36500000 | H21: =SUM(D21:G21) -> 36500000 | I21: =H21*0.11 -> 4015000 | J21: =H21+I21 -> 40515000 | L21: 45707 | N21: =J21-M21 -> 40515000 | P21: =J21-M21-N21 -> 0
A22: 45708 | B22: 83/INV/IP/II/2025 | C22: PT. Indoporlen | F22: 32452500 | H22: =SUM(D22:G22) -> 32452500 | I22: =H22*0.11 -> 3569775 | J22: =H22+I22 -> 36022275 | N22: 0 | P22: =J22-M22-N22 -> 36022275
A23: 45708 | B23: 97/INV/IP/II/2025 | C23: PT. Indoporlen | F23: 9900000 | H23: =SUM(D23:G23) -> 9900000 | I23: =H23*0.11 -> 1089000 | J23: =H23+I23 -> 10989000 | N23: 0 | P23: =J23-M23-N23 -> 10989000
A24: 45712 | B24: SI-2502013 | C24: PT. Caprefindo | F24: 26250000 | H24: =SUM(D24:G24) -> 26250000 | I24: =H24*0.11 -> 2887500 | J24: =H24+I24 -> 29137500 | N24: 0 | P24: =J24-M24-N24 -> 29137500
A25: 45714 | B25: 2025/AMS/0011 | C25: PT. Allied Makmur Service | F25: 79546250 | H25: =SUM(D25:G25) -> 79546250 | I25: =H25*0.11 -> 8750087.5 | J25: =H25+I25 -> 88296338 | N25: 0 | P25: =J25-M25-N25 -> 88296338
A26: 45714 | B26: 45/J/II/25 | C26: PT. Jaya Refractorindo Utama | F26: 7500000 | H26: =SUM(D26:G26) -> 7500000 | I26: =H26*0.11 -> 825000 | J26: =H26+I26 -> 8325000 | L26: 45707 | N26: =J26-M26 -> 8325000 | P26: =J26-M26-N26 -> 0
A27: 45714 | B27: 0238/INV-MULA/II-25 | C27: PT. Mitra Utama Lestari Abadi | F27: 33300000 | H27: =SUM(D27:G27) -> 33300000 | I27: =H27*0.11 -> 3663000 | J27: =H27+I27 -> 36963000 | N27: 0 | P27: =J27-M27-N27 -> 36963000
A28: 45715 | B28: 011C/INV/DMP-GTP/II/25 | C28: PT. Dwitama Metal Presisi | E28: 8000000 | H28: =SUM(D28:G28) -> 8000000 | I28: =H28*0.11 -> 880000 | J28: =H28+I28 -> 8880000 | L28: 45716 | N28: =J28-M28 -> 8880000 | P28: =J28-M28-N28 -> 0
H29: =SUM(D29:G29) -> 0 | I29: =H29*0.11 -> 0 | J29: =H29+I29 -> 0 | N29: =J29-M29 -> 0 | P29: =J29-M29-N29 -> 0
H30: =SUM(D30:G30) -> 0 | I30: =H30*0.11 -> 0 | J30: =H30+I30 -> 0 | N30: 0 | P30: =J30-M30-N30 -> 0
H31: =SUM(D31:G31) -> 0 | I31: =H31*0.11 -> 0 | J31: =H31+I31 -> 0 | N31: 0 | P31: =J31-M31-N31 -> 0
H32: =SUM(D32:G32) -> 0 | I32: =H32*0.11 -> 0 | J32: =H32+I32 -> 0 | N32: =J32-M32 -> 0 | P32: =J32-M32-N32 -> 0
H33: =SUM(D33:G33) -> 0 | I33: =H33*0.11 -> 0 | J33: =H33+I33 -> 0 | N33: =J33-M33 -> 0 | P33: =J33-M33-N33 -> 0
C34: Total | D34: =SUM(D7:D33) -> 12000000 | E34: =SUM(E7:E33) -> 274285000 | F34: =SUM(F7:F33) -> 1.182032e+09 | G34: =SUM(G7:G33) -> 0 | H34: =SUM(H7:H33) -> 1.468317e+09 | I34: =SUM(I7:I33) -> 1.5989787e+08 | J34: =SUM(J7:J33) -> 1.6282149e+09 | M34: =SUM(M7:M33) -> 0 | N34: =SUM(N7:N33) -> 482207850 | P34: =SUM(P7:P33) -> 1.146007e+09 | U34: =SUM(U7:U33) -> 0
U35: =#REF!-U34 -> #REF!

Sheet INV MARET
A1: Kewajiban GMT Maret 2025
A4: PPN
A5: Tanggal | B5: No. Invoice | C5: SUPPLIER | D5: Keterangan | L5: Tgl Pembayaran | M5: Potongan PPH 2% | N5: Nilai Pembayaran | P5: Saldo AP
D6: Jasa | E6: Anchor | F6: Material | G6: Sewa Alat | H6: Total | I6: PPN | J6: Grand Total
A7: 45723 | B7: 0588/KWT/URP/II/2025 | C7: PT. Upaya Riksa Patra | D7: 38400000 | H7: =SUM(D7:G7) -> 38400000 | I7: =H7*0.11 -> 4224000 | J7: =H7+I7 -> 42624000 | L7: 45723 | N7: =J7-M7 -> 42624000 | P7: =J7-M7-N7 -> 0
A8: 45722 | B8: 0189/SKN/III/2025 | C8: PT. Sarana Katiga Nusantara | D8: 18000000 | H8: =SUM(D8:G8) -> 18000000 | I8: =H8*0.11 -> 1980000 | J8: =H8+I8 -> 19980000 | L8: 45722 | N8: =J8-M8 -> 19980000 | P8: =J8-M8-N8 -> 0
A9: 45721 | B9: 006/PH-CV.ASM/II/2025 | C9: CV. Aurora Sheet Metal | D9: 10000000 | H9: =SUM(D9:G9) -> 10000000 | I9: 0 | J9: =H9+I9 -> 10000000 | L9: 45721 | N9: =J9-M9 -> 10000000 | P9: =J9-M9-N9 -> 0
A10: 45730 | B10: 032/INV-S3/II-25 | C10: PT. Surya Semesta Sakti | F10: 35000000 | H10: =SUM(D10:G10) -> 35000000 | I10: =H10*0.11 -> 3850000 | J10: =H10+I10 -> 38850000 | N10: 0 | P10: =J10-M10-N10 -> 38850000
A11: 45733 | B11: 159 | C11: Suwarso | D11: 5430000 | H11: =SUM(D11:G11) -> 5430000 | I11: 0 | J11: =H11+I11 -> 5430000 | N11: 0 | P11: =J11-M11-N11 -> 5430000
A12: 45740 | B12: SI-2503022 | C12: PT. Caprefindo | F12: =500*42000 -> 21000000 | H12: =SUM(D12:G12) -> 21000000 | I12: =H12*0.11 -> 2310000 | J12: =H12+I12 -> 23310000 | N12: 0 | P12: =J12-M12-N12 -> 23310000
A13: 45741 | B13: 0422/Inv-Mula/III-25 | C13: PT. Mitra Utama Lestari Abadi | F13: 43300000 | H13: =SUM(D13:G13) -> 43300000 | I13: =H13*0.11 -> 4763000 | J13: =H13+I13 -> 48063000 | N13: 0 | P13: =J13-M13-N13 -> 48063000
A14: 45740 | B14: 93/J/III/25 | C14: PT. Jaya Refractorindo Utama | F14: 33000000 | H14: =SUM(D14:G14) -> 33000000 | I14: =H14*0.11 -> 3630000 | J14: =H14+I14 -> 36630000 | L14: 45740 | N14: =J14-M14 -> 36630000 | P14: =J14-M14-N14 -> 0
A15: 45740 | B15: 95/J/III/25 | C15: PT. Jaya Refractorindo Utama | F15: 15000000 | H15: =SUM(D15:G15) -> 15000000 | I15: =H15*0.11 -> 1650000 | J15: =H15+I15 -> 16650000 | L15: 45740 | N15: =J15-M15 -> 16650000 | P15: =J15-M15-N15 -> 0
A16: 45740 | B16: 102/J/III/25 | C16: PT. Jaya Refractorindo Utama | F16: 10500000 | H16: =SUM(D16:G16) -> 10500000 | I16: =H16*0.11 -> 1155000 | J16: =H16+I16 -> 11655000 | L16: 45740 | N16: =J16-M16 -> 11655000 | P16: =J16-M16-N16 -> 0
H17: =SUM(D17:G17) -> 0 | I17: =H17*0.11 -> 0 | J17: =H17+I17 -> 0 | N17: =J17-M17 -> 0 | P17: =J17-M17-N17 -> 0
H18: =SUM(D18:G18) -> 0 | I18: =H18*0.11 -> 0 | J18: =H18+I18 -> 0 | N18: =J18-M18 -> 0 | P18: =J18-M18-N18 -> 0
H19: =SUM(D19:G19) -> 0 | I19: =H19*0.11 -> 0 | J19: =H19+I19 -> 0 | N19: 0 | P19: =J19-M19-N19 -> 0
H20: =SUM(D20:G20) -> 0 | I20: =H20*0.11 -> 0 | J20: =H20+I20 -> 0 | N20: 0 | P20: =J20-M20-N20 -> 0
H21: =SUM(D21:G21) -> 0 | I21: =H21*0.11 -> 0 | J21: =H21+I21 -> 0 | N21: 0 | P21: =J21-M21-N21 -> 0
H22: =SUM(D22:G22) -> 0 | I22: =H22*0.11 -> 0 | J22: =H22+I22 -> 0 | N22: 0 | P22: =J22-M22-N22 -> 0
H23: =SUM(D23:G23) -> 0 | I23: =H23*0.11 -> 0 | J23: =H23+I23 -> 0 | N23: 0 | P23: =J23-M23-N23 -> 0
H24: =SUM(D24:G24) -> 0 | I24: =H24*0.11 -> 0 | J24: =H24+I24 -> 0 | N24: =J24-M24 -> 0 | P24: =J24-M24-N24 -> 0
H25: =SUM(D25:G25) -> 0 | I25: =H25*0.11 -> 0 | J25: =H25+I25 -> 0 | M25: 0 | N25: =J25-M25 -> 0 | P25: =J25-M25-N25 -> 0
H26: =SUM(D26:G26) -> 0 | I26: =H26*0.11 -> 0 | J26: =H26+I26 -> 0 | M26: 0 | N26: 0 | P26: =J26-M26-N26 -> 0
H27: =SUM(D27:G27) -> 0 | I27: =H27*0.11 -> 0 | J27: =H27+I27 -> 0 | N27: 0 | P27: =J27-M27-N27 -> 0
H28: =SUM(D28:G28) -> 0 | I28: =H28*0.11 -> 0 | J28: =H28+I28 -> 0 | N28: =J28-M28 -> 0 | P28: =J28-M28-N28 -> 0
H29: =SUM(D29:G29) -> 0 | I29: =H29*0.11 -> 0 | J29: =H29+I29 -> 0 | M29: =D29*0.02 -> 0 | N29: =J29-M29 -> 0 | P29: =J29-M29-N29 -> 0
C30: Total | D30: =SUM(D7:D29) -> 71830000 | E30: =SUM(E7:E29) -> 0 | F30: =SUM(F7:F29) -> 157800000 | G30: =SUM(G7:G29) -> 0 | H30: =SUM(H7:H29) -> 229630000 | I30: =SUM(I7:I29) -> 23562000 | J30: =SUM(J7:J29) -> 253192000 | M30: =SUM(M7:M29) -> 0 | N30: =SUM(N7:N29) -> 137539000 | P30: =SUM(P7:P29) -> 115653000 | U30: =SUM(U7:U29) -> 0
U31: =M30-U30 -> 0

Sheet INV APRIL
A1: Kewajiban GMT April 2025
A3: PPN
A4: Tanggal | B4: No. Invoice | C4: Supplier | D4: Keterangan | L4: Tgl Pembayaran | M4: Potongan PPH 2% | N4: Beban Admin | O4: Nilai Pembayaran | Q4: Saldo AP
D5: Jasa | E5: Anchor | F5: Material | G5: Sewa Alat | H5: Total | I5: PPN | J5: Grand Total
A6: 45755 | B6: 3259000271 | C6: PT. Indoporlen | F6: =14000*25000 -> 350000000 | H6: =SUM(D6:G6) -> 350000000 | I6: =H6*0.11 -> 38500000 | J6: =H6+I6 -> 388500000 | M6: 0 | O6: 0 | Q6: =J6-M6-N6-O6 -> 388500000
A7: 45755 | B7: 150/INV/IP/III/2025 | C7: PT. Indoporlen | F7: =16500*450 -> 7425000 | H7: =SUM(D7:G7) -> 7425000 | I7: =H7*0.11 -> 816750 | J7: =H7+I7 -> 8241750 | O7: 0 | Q7: =J7-M7-N7-O7 -> 8241750
A8: 45756 | B8: 2520121 | C8: PT. Shinagawa Refractech Perkasa | F8: =6510*15000 -> 97650000 | H8: =SUM(D8:G8) -> 97650000 | I8: =H8*0.11 -> 10741500 | J8: =H8+I8 -> 108391500 | O8: 0 | Q8: =J8-M8-N8-O8 -> 108391500
A9: 45756 | B9: 3259000275 | C9: PT. Indoporlen | F9: =1200*25000 -> 30000000 | H9: =SUM(D9:G9) -> 30000000 | I9: =H9*0.11 -> 3300000 | J9: =H9+I9 -> 33300000 | N9: 0 | O9: 0 | Q9: =J9-M9-N9-O9 -> 33300000
A10: 45756 | B10: 3259000274 | C10: PT. Indoporlen | F10: =25000*1000 -> 25000000 | H10: =SUM(D10:G10) -> 25000000 | I10: =H10*0.11 -> 2750000 | J10: =H10+I10 -> 27750000 | N10: 0 | O10: 0 | Q10: =J10-M10-N10-O10 -> 27750000
A11: 45763 | B11: 3259000273 | C11: PT. Indoporlen | F11: 1479000000 | H11: =SUM(D11:G11) -> 1479000000 | I11: =H11*0.11 -> 162690000 | J11: =H11+I11 -> 1641690000 | O11: 0 | Q11: =J11-M11-N11-O11 -> 1641690000
A12: 45763 | B12: 3259000285 | C12: PT. Indoporlen | F12: 21470000 | H12: =SUM(D12:G12) -> 21470000 | I12: 0 | J12: =H12+I12 -> 21470000 | O12: 0 | Q12: =J12-M12-N12-O12 -> 21470000
A13: 45763 | B13: 2025/AMS/0030 | C13: PT. Allied Makmur Servis | F13: 246180000 | H13: =SUM(D13:G13) -> 246180000 | I13: =H13*0.11 -> 27079800 | J13: =H13+I13 -> 273259800 | O13: 0 | Q13: =J13-M13-N13-O13 -> 273259800
A14: 45763 | B14: 0237/TP/INV/III/25 | C14: CV. Tehnik Perdana | D14: 10500000 | H14: =SUM(D14:G14) -> 10500000 | I14: =H14*0.11 -> 1155000 | J14: =H14+I14 -> 11655000 | L14: 45730 | O14: =J14-M14-N14 -> 11655000 | Q14: =J14-M14-N14-O14 -> 0
A15: 45763 | B15: 0283/TP/INV/IV/25 | C15: CV. Tehnik Perdana | D15: 14500000 | H15: =SUM(D15:G15) -> 14500000 | I15: =H15*0.11 -> 1595000 | J15: =H15+I15 -> 16095000 | L15: 45756 | O15: =J15-M15-N15 -> 16095000 | Q15: =J15-M15-N15-O15 -> 0
A16: 45768 | B16: SI-2504009 | C16: PT. Caprefindo | F16: 26250000 | H16: =SUM(D16:G16) -> 26250000 | I16: =H16*0.11 -> 2887500 | J16: =H16+I16 -> 29137500 | O16: 0 | Q16: =J16-M16-N16-O16 -> 29137500
A17: 45771 | B17: 067/INV-ASM/IV/2025 | C17: CV. Aurora Sheet Metal | F17: 1837500 | H17: =SUM(D17:G17) -> 1837500 | I17: =H17*0.11 -> 202125 | J17: =H17+I17 -> 2039625 | L17: 45770 | O17: =J17-M17-N17 -> 2039625 | Q17: =J17-M17-N17-O17 -> 0
A18: 45772 | B18: 1342163408 | C18: PT. Kawan Lama Sejahtera | F18: 5466440 | H18: =SUM(D18:G18) -> 5466440 | I18: =H18*0.11 -> 601308.4 | J18: =H18+I18 -> 6067748.4 | L18: 45735 | O18: =J18-M18-N18 -> 6067748.4 | Q18: =J18-M18-N18-O18 -> 0
A19: 45777 | B19: SI-2504021 | C19: PT. Caprefindo | F19: 12600000 | H19: =SUM(D19:G19) -> 12600000 | I19: =H19*0.11 -> 1386000 | J19: =H19+I19 -> 13986000 | O19: 0 | Q19: =J19-M19-N19-O19 -> 13986000
A20: 45777 | B20: 051/INV-S3/IV-25 | C20: PT. Surya Semesta Sakti | F20: 3200000 | H20: =SUM(D20:G20) -> 3200000 | I20: =H20*0.11 -> 352000 | J20: =H20+I20 -> 3552000 | O20: 0 | Q20: =J20-M20-N20-O20 -> 3552000
A21: 45777 | B21: 193/INV/IP/IV/2025 | C21: PT. Indoporlen | F21: 13000000 | H21: =SUM(D21:G21) -> 13000000 | I21: =H21*0.11 -> 1430000 | J21: =H21+I21 -> 14430000 | O21: 0 | Q21: =J21-M21-N21-O21 -> 14430000
A22: 45777 | B22: 192/INV/IP/IV/2025 | C22: PT. Indoporlen | F22: 13300000 | H22: =SUM(D22:G22) -> 13300000 | I22: =H22*0.11 -> 1463000 | J22: =H22+I22 -> 14763000 | O22: 0 | Q22: =J22-M22-N22-O22 -> 14763000
A23: 45771 | B23: 37/J/IV/25 | C23: PT. Jarefu | F23: 14000000 | H23: =SUM(D23:G23) -> 14000000 | I23: =H23*0.11 -> 1540000 | J23: =H23+I23 -> 15540000 | L23: 45771 | O23: =J23-M23-N23 -> 15540000 | Q23: =J23-M23-N23-O23 -> 0
A24: 45754 | B24: 1342177918 | C24: PT. Kawan Lama Sejahtera | F24: 8574800 | H24: =SUM(D24:G24) -> 8574800 | I24: =H24*0.11 -> 943228 | J24: =H24+I24 -> 9518028 | L24: 45754 | O24: =J24-M24-N24 -> 9518028 | Q24: =J24-M24-N24-O24 -> 0
A25: 45776 | B25: WIP/0445/T/IV/2025 | C25: PT. Willich Isolasi Pratama | F25: 17000000 | H25: =SUM(D25:G25) -> 17000000 | I25: =H25*0.11 -> 1870000 | J25: =H25+I25 -> 18870000 | L25: 45776 | O25: =J25-M25-N25 -> 18870000 | Q25: =J25-M25-N25-O25 -> 0
A26: 45776 | B26: WIP/0425/T/IV/2025 | C26: PT. Willich Isolasi Pratama | F26: 14000000 | H26: =SUM(D26:G26) -> 14000000 | I26: =H26*0.11 -> 1540000 | J26: =H26+I26 -> 15540000 | L26: 45776 | O26: =J26-M26-N26 -> 15540000 | Q26: =J26-M26-N26-O26 -> 0
H27: =SUM(D27:G27) -> 0 | I27: =H27*0.11 -> 0 | J27: =H27+I27 -> 0 | M27: =G27*0.02 -> 0 | O27: =J27-M27-N27 -> 0 | Q27: =J27-M27-N27-O27 -> 0
C28: Total | D28: =SUM(D6:D27) -> 25000000 | E28: =SUM(E6:E27) -> 0 | F28: =SUM(F6:F27) -> 2385953740 | G28: =SUM(G6:G27) -> 0 | H28: =SUM(H6:H27) -> 2410953740 | I28: =SUM(I6:I27) -> 2.6284321e+08 | J28: =SUM(J6:J27) -> 2.673797e+09 | M28: =SUM(M6:M27) -> 0 | N28: =SUM(N6:N27) -> 0 | O28: =SUM(O6:O27) -> 95325401 | Q28: =SUM(Q6:Q27) -> 2578471550 | V28: =SUM(V6:V27) -> 0
V29: =M28-V28 -> 0
H33: =22700/500 -> 45.4
H34: =46/12 -> 3.8333333
H35: =15000000*5 -> 75000000
H36: =H35/22700 -> 3303.9648

Sheet INV MEI
A1: Kewajiban GMT Mei 2025
J2: =J10+J11+J12+J13 -> 61813125
A3: PPN
A4: Tanggal | B4: No. Invoice | C4: Supplier | D4: Keterangan | L4: Tgl Pembayaran | M4: Potongan PPH 2% | N4: Beban Admin | O4: Nilai Pembayaran | Q4: Saldo AP
D5: Jasa | E5: Anchor | F5: Material | G5: Sewa Alat | H5: Total | I5: PPN | J5: Grand Total
A6: 45799 | B6: 330/INV/IP/V/2025 | C6: PT. Indoporlen | F6: 12483000 | H6: =SUM(D6:G6) -> 12483000 | I6: =H6*0.11 -> 1373130 | J6: =H6+I6 -> 13856130 | L6: 45824 | O6: =J6-M6-N6 -> 13856130 | Q6: =J6-M6-N6-O6 -> 0
A7: 45799 | B7: 229/INV/IP/V/2025 | C7: PT. Indoporlen | F7: 16000000 | H7: =SUM(D7:G7) -> 16000000 | I7: =H7*0.11 -> 1760000 | J7: =H7+I7 -> 17760000 | L7: 45824 | M7: =D7*0.02 -> 0 | O7: =J7-M7-N7 -> 17760000 | Q7: =J7-M7-N7-O7 -> 0
A8: 45779 | B8: 77/PO/GMT/V/2025 | C8: CV. Putra Indra Boga | F8: 58500000 | H8: =SUM(D8:G8) -> 58500000 | I8: =H8*0.11 -> 6435000 | J8: =H8+I8 -> 64935000 | L8: 45779 | O8: =J8-M8-N8 -> 64935000 | Q8: =J8-M8-N8-O8 -> 0
A9: 45790 | B9: 79/PO/GMT/V/2025 | C9: CV. Putra Indra Boga | F9: 71250000 | H9: =SUM(D9:G9) -> 71250000 | I9: =H9*0.11 -> 7837500 | J9: =H9+I9 -> 79087500 | L9: 45790 | O9: =J9-M9-N9 -> 79087500 | Q9: =J9-M9-N9-O9 -> 0
A10: 45796 | B10: 82/PO/GMT/V/2025 | C10: CV. Putra Indra Boga | F10: 55687500 | H10: =SUM(D10:G10) -> 55687500 | I10: =H10*0.11 -> 6125625 | J10: =H10+I10 -> 61813125 | L10: 45796 | O10: =J10-M10-N10 -> 61813125 | Q10: =J10-M10-N10-O10 -> 0
H11: =SUM(D11:G11) -> 0 | I11: =H11*0.11 -> 0 | J11: =H11+I11 -> 0 | O11: =J11-M11-N11 -> 0 | Q11: =J11-M11-N11-O11 -> 0
H12: =SUM(D12:G12) -> 0 | I12: =H12*0.11 -> 0 | J12: =H12+I12 -> 0 | O12: =J12-M12-N12 -> 0 | Q12: =J12-M12-N12-O12 -> 0
H13: =SUM(D13:G13) -> 0 | I13: =H13*0.11 -> 0 | J13: =H13+I13 -> 0 | O13: =J13-M13-N13 -> 0 | Q13: =J13-M13-N13-O13 -> 0
H14: =SUM(D14:G14) -> 0 | I14: 0 | J14: =H14+I14 -> 0 | O14: =J14-M14-N14 -> 0 | Q14: =J14-M14-N14-O14 -> 0
H15: =SUM(D15:G15) -> 0 | I15: =H15*0.11 -> 0 | J15: =H15+I15 -> 0 | O15: =J15-M15-N15 -> 0 | Q15: =J15-M15-N15-O15 -> 0
H16: =SUM(D16:G16) -> 0 | I16: =H16*0.11 -> 0 | J16: =H16+I16 -> 0 | O16: =J16-M16-N16 -> 0 | Q16: =J16-M16-N16-O16 -> 0
H17: =SUM(D17:G17) -> 0 | I17: 0 | J17: =H17+I17 -> 0 | O17: =J17-M17-N17 -> 0 | Q17: =J17-M17-N17-O17 -> 0
H18: =SUM(D18:G18) -> 0 | I18: =H18*0.11 -> 0 | J18: =H18+I18 -> 0 | M18: =D18*0.02 -> 0 | O18: =J18-M18-N18 -> 0 | Q18: =J18-M18-N18-O18 -> 0
C19: Total | D19: =SUM(D6:D18) -> 0 | E19: =SUM(E6:E18) -> 0 | F19: =SUM(F6:F18) -> 213920500 | G19: =SUM(G6:G18) -> 0 | H19: =SUM(H6:H18) -> 213920500 | I19: =SUM(I6:I18) -> 23531255 | J19: =SUM(J6:J18) -> 237451755 | M19: =SUM(M6:M18) -> 0 | N19: =SUM(N6:N18) -> 0 | O19: =SUM(O6:O18) -> 237451755 | Q19: =SUM(Q6:Q18) -> 0 | V19: =SUM(V6:V18) -> 0
V20: =M19-V19 -> 0

Sheet INV JUNI
A1: Kewajiban GMT Juni 2025
A3: PPN
A4: Tanggal | B4: No. Invoice | C4: Supplier | D4: Keterangan | L4: Tgl Pembayaran | M4: Potongan PPH 2% | N4: Nilai Pembayaran | P4: Saldo AP
D5: Jasa | E5: Anchor | F5: Material | G5: Sewa Alat | H5: Total | I5: PPN | J5: Grand Total
A6: 45813 | B6: 107/INV-ASM/VI/2025 | C6: CV. Aurora Sheet Metal | D6: 2500000 | H6: =SUM(D6:G6) -> 2500000 | I6: =H6*0.11 -> 275000 | J6: =H6+I6 -> 2775000 | L6: 45813 | N6: =J6-M6 -> 2775000 | P6: =J6-M6-N6 -> 0
A7: 45813 | B7: 85/GMT/PO/VI/2025 | C7: CV. Putra Indra Boga | F7: 36500000 | H7: =SUM(D7:G7) -> 36500000 | I7: =H7*0.11 -> 4015000 | J7: =H7+I7 -> 40515000 | L7: 45813 | N7: =J7-M7 -> 40515000 | P7: =J7-M7-N7 -> 0
A8: 45818 | B8: 87/GMT/PO/VI/2025 | C8: CV. Putra Indra Boga | F8: 29929150 | H8: =SUM(D8:G8) -> 29929150 | I8: =H8*0.11 -> 3292206.5 | J8: =H8+I8 -> 33221356 | L8: 45818 | N8: =J8-M8 -> 33221356 | P8: =J8-M8-N8 -> 0
A9: 45818 | B9: 271/INV/IP/VI/2025 | C9: PT. Indoporlen | F9: 16000000 | H9: =SUM(D9:G9) -> 16000000 | I9: =H9*0.11 -> 1760000 | J9: =H9+I9 -> 17760000 | L9: 45849 | N9: =J9-M9 -> 17760000 | P9: =J9-M9-N9 -> 0
A10: 45821 | B10: 036C/INV/DMP-GTP/VI/25 | C10: PT. Dwitama Metal Presisi | F10: 6175000 | H10: =SUM(D10:G10) -> 6175000 | I10: =H10*0.11 -> 679250 | J10: =H10+I10 -> 6854250 | L10: 45849 | N10: =J10-M10 -> 6854250 | P10: =J10-M10-N10 -> 0
A11: 45821 | B11: 88/GMT/PO/VI/2025 | C11: CV. Putra Indra Boga | F11: 21750000 | H11: =SUM(D11:G11) -> 21750000 | I11: =H11*0.11 -> 2392500 | J11: =H11+I11 -> 24142500 | L11: 45821 | N11: =J11-M11 -> 24142500 | P11: =J11-M11-N11 -> 0
A12: 45827 | B12: 89/GMT/PO/VI/2025 | C12: CV. Putra Indra Boga | F12: 77212500 | H12: =SUM(D12:G12) -> 77212500 | I12: =H12*0.11 -> 8493375 | J12: =H12+I12 -> 85705875 | L12: 45827 | N12: =J12-M12 -> 85705875 | P12: =J12-M12-N12 -> 0
A13: 45826 | B13: 90/GMT/PO/VI/2025 | C13: CV. Putra Indra Boga | F13: 1750000 | H13: =SUM(D13:G13) -> 1750000 | I13: =H13*0.11 -> 192500 | J13: =H13+I13 -> 1942500 | L13: 45826 | N13: =J13-M13 -> 1942500 | P13: =J13-M13-N13 -> 0
A14: 45831 | B14: 91/GMT/PO/VI/2025 | C14: CV. Putra Indra Boga | F14: 146000000 | H14: =SUM(D14:G14) -> 146000000 | I14: =H14*0.11 -> 16060000 | J14: =H14+I14 -> 162060000 | L14: 45831 | N14: =J14-M14 -> 162060000 | P14: =J14-M14-N14 -> 0
A15: 45834 | B15: 92/GMT/PO/VI/2025 | C15: CV. Putra Indra Boga | F15: 54750000 | H15: =SUM(D15:G15) -> 54750000 | I15: =H15*0.11 -> 6022500 | J15: =H15+I15 -> 60772500 | L15: 45834 | N15: =J15-M15 -> 60772500 | P15: =J15-M15-N15 -> 0
A16: 45828 | B16: 114/INV-ASM/VI/2025 | C16: CV. Aurora Sheet Metal | D16: 750000 | H16: =SUM(D16:G16) -> 750000 | I16: =H16*0.11 -> 82500 | J16: =H16+I16 -> 832500 | L16: 45828 | N16: =J16-M16 -> 832500 | P16: =J16-M16-N16 -> 0
A17: 45833 | B17: 0010/INV/06/25 | C17: PT. Indobricks Sejahtera | F17: 22140000 | H17: =SUM(D17:G17) -> 22140000 | I17: =H17*0.11 -> 2435400 | J17: =H17+I17 -> 24575400 | L17: 45833 | N17: =J17-M17 -> 24575400 | P17: =J17-M17-N17 -> 0
H18: =SUM(D18:G18) -> 0 | I18: =H18*0.11 -> 0 | J18: =H18+I18 -> 0 | N18: =J18-M18 -> 0 | P18: =J18-M18-N18 -> 0
H19: =SUM(D19:G19) -> 0 | I19: =H19*0.11 -> 0 | J19: =H19+I19 -> 0 | N19: =J19-M19 -> 0 | P19: =J19-M19-N19 -> 0
H20: =SUM(D20:G20) -> 0 | I20: =H20*0.11 -> 0 | J20: =H20+I20 -> 0 | M20: =D20*0.02 -> 0 | N20: =J20-M20 -> 0 | P20: =J20-M20-N20 -> 0
C21: Total | D21: =SUM(D6:D20) -> 3250000 | E21: =SUM(E6:E20) -> 0 | F21: =SUM(F6:F20) -> 412206650 | G21: =SUM(G6:G20) -> 0 | H21: =SUM(H6:H20) -> 415456650 | I21: =SUM(I6:I20) -> 45700232 | J21: =SUM(J6:J20) -> 4.6115688e+08 | M21: =SUM(M6:M20) -> 0 | N21: =SUM(N6:N20) -> 4.6115688e+08 | P21: =SUM(P6:P20) -> 0

Sheet INV JULI
A1: Account Payable GMT Juli 2025
A3: PPN
A4: Tanggal | B4: No. Invoice | C4: Supplier | D4: Keterangan | L4: Tgl Pembayaran | M4: Potongan PPH 2% | N4: Beban Admin | O4: Nilai Pembayaran | Q4: Saldo AR
D5: Jasa | E5: Anchor | F5: Material | G5: Sewa Alat | H5: Total | I5: PPN | J5: Grand Total
A6: 45853 | B6: 96/PO/GMT/VII/2025 | C6: CV. Putra Indra Boga | F6: 235880000 | H6: =SUM(D6:G6) -> 235880000 | I6: =H6*0.11 -> 25946800 | J6: =H6+I6 -> 261826800 | L6: 45853 | O6: =J6-M6-N6 -> 261826800 | Q6: =J6-M6-N6-O6 -> 0
A7: 45854 | B7: SI-2507019 | C7: PT. Caprefindo | F7: 26250000 | H7: =SUM(D7:G7) -> 26250000 | I7: =H7*0.11 -> 2887500 | J7: =H7+I7 -> 29137500 | L7: 45898 | O7: =J7-M7-N7 -> 29137500 | Q7: =J7-M7-N7-O7 -> 0
A8: 45862 | B8: 104/PO/GMT/VII/2025 | C8: CV. Putra Indra Boga | F8: 6982500 | H8: =SUM(D8:G8) -> 6982500 | I8: =H8*0.11 -> 768075 | J8: =H8+I8 -> 7750575 | L8: 45862 | O8: =J8-M8-N8 -> 7750575 | Q8: =J8-M8-N8-O8 -> 0
A9: 45863 | B9: 0975/INV-MULA/VII-25 | C9: PT. Mitra Utama Lestari Abadi | F9: 20000000 | H9: =SUM(D9:G9) -> 20000000 | I9: =H9*0.11 -> 2200000 | J9: =H9+I9 -> 22200000 | L9: 45898 | O9: =J9-N9 -> 22200000 | Q9: =J9-M9-N9-O9 -> 0
A10: 45863 | B10: WIP/0777/T/VII/2025 | C10: PT. Willich Isolasi Pratama | F10: 17000000 | H10: =SUM(D10:G10) -> 17000000 | I10: =H10*0.11 -> 1870000 | J10: =H10+I10 -> 18870000 | L10: 45862 | O10: =J10-M10-N10 -> 18870000 | Q10: =J10-M10-N10-O10 -> 0 | V10: =M10 -> 0
A11: 45866 | B11: 105/PO/GMT/VII/2025 | C11: CV. Putra Indra Boga | F11: 105971700 | H11: =SUM(D11:G11) -> 105971700 | I11: =H11*0.11 -> 11656887 | J11: =H11+I11 -> 117628587 | L11: 45866 | O11: =J11-M11-N11 -> 117628587 | Q11: =J11-M11-N11-O11 -> 0
A12: 45868 | B12: 108/PO/GMT/VII/2025 | C12: CV. Putra Indra Boga | F12: 78029115 | H12: =SUM(D12:G12) -> 78029115 | I12: =H12*0.11 -> 8583202.7 | J12: =H12+I12 -> 86612318 | L12: 45868 | O12: =J12-M12-N12 -> 86612318 | Q12: =J12-M12-N12-O12 -> 0
A13: 45868 | B13: 1016/INV-MULA/VII-25 | C13: PT. Mitra Utama Lestari Abadi | F13: 18000000 | H13: =SUM(D13:G13) -> 18000000 | I13: =H13*0.11 -> 1980000 | J13: =H13+I13 -> 19980000 | L13: 45898 | O13: =J13-M13-N13 -> 19980000 | Q13: =J13-M13-N13-O13 -> 0
A14: 45868 | B14: 171 | C14: Suwarso | D14: 2330000 | H14: =SUM(D14:G14) -> 2330000 | I14: 0 | J14: =H14+I14 -> 2330000 | L14: 45884 | O14: =J14-M14-N14 -> 2330000 | Q14: =J14-M14-N14-O14 -> 0
A15: 45869 | B15: 377/Inv/Ip/VII/2025 | C15: PT. Indoporlen | F15: 330000000 | H15: =SUM(D15:G15) -> 330000000 | I15: =H15*0.11 -> 36300000 | J15: =H15+I15 -> 366300000 | L15: 45917 | O15: =J15-M15-N15 -> 366300000 | Q15: =J15-M15-N15-O15 -> 0 | V15: =M15 -> 0
A16: 45869 | B16: 2025/AMS/0099 | C16: PT. Allied Makmur Servis | F16: 22380000 | H16: =SUM(D16:G16) -> 22380000 | I16: =H16*0.11 -> 2461800 | J16: =H16+I16 -> 24841800 | L16: 45917 | M16: 0 | O16: =J16-N16 -> 24841800 | Q16: =J16-M16-N16-O16 -> 0 | V16: =M16 -> 0
A17: 45869 | B17: 110/PO/GMT/VII/2025 | C17: CV. Putra Indra Boga | F17: 34965000 | H17: =SUM(D17:G17) -> 34965000 | I17: =H17*0.11 -> 3846150 | J17: =H17+I17 -> 38811150 | L17: 45869 | O17: =J17-M17-N17 -> 38811150 | Q17: =J17-M17-N17-O17 -> 0
A18: 45868 | B18: WIP/0802/T/VII/2025 | C18: PT. Willich Isolasi Pratama | F18: 8500000 | H18: =SUM(D18:G18) -> 8500000 | I18: =H18*0.11 -> 935000 | J18: =H18+I18 -> 9435000 | L18: 45867 | M18: 0 | O18: =J18-M18-N18 -> 9435000 | Q18: =J18-M18-N18-O18 -> 0
A19: 45866 | C19: Ajen Mustopa | F19: 21000000 | H19: =SUM(D19:G19) -> 21000000 | I19: 0 | J19: =H19+I19 -> 21000000 | L19: 45896 | O19: =J19-M19-N19 -> 21000000
H20: =SUM(D20:G20) -> 0 | I20: =H20*0.11 -> 0 | J20: =H20+I20 -> 0 | O20: 0 | Q20: =J20-M20-N20-O20 -> 0
C21: Total | D21: =SUM(D6:D20) -> 2330000 | E21: =SUM(E6:E20) -> 0 | F21: =SUM(F6:F20) -> 924958315 | G21: =SUM(G6:G20) -> 0 | H21: =SUM(H6:H20) -> 927288315 | I21: =SUM(I6:I20) -> 99435415 | J21: =SUM(J6:J20) -> 1.0267237e+09 | M21: =SUM(M6:M20) -> 0 | N21: =SUM(N6:N20) -> 0 | O21: =SUM(O6:O20) -> 1.0267237e+09 | Q21: =SUM(Q6:Q20) -> 0 | S21: =SUM(S6:S20) -> 0 | T21: =SUM(T6:T20) -> 0 | V21: =SUM(V6:V20) -> 0
V22: =M21-V21 -> 0

Sheet INV AGUSTUS
A1: Kewajiban GMT Agustus 2025
A3: PPN
A5: Tanggal | B5: No. Invoice | C5: Supplier | D5: Keterangan | L5: Tgl Pembayaran | M5: Beban Admin | N5: Nilai Pembayaran | P5: Saldo AP
D6: Jasa | E6: Anchor | F6: Material | G6: Sewa Alat | H6: Total | I6: PPN | J6: Grand Total
A7: 45876 | B7: 3259000639 | C7: PT. Indoporlen | F7: 16000000 | H7: =SUM(D7:G7) -> 16000000 | I7: =H7*0.11 -> 1760000 | J7: =SUM(H7:I7) -> 17760000 | L7: 45917 | M7: 0 | N7: =J7-M7 -> 17760000 | P7: =J7-M7-N7 -> 0
A8: 45876 | B8: 392/INV/IP/VIII/2025 | C8: PT. Indoporlen | F8: 37170000 | H8: =SUM(D8:G8) -> 37170000 | I8: =H8*0.11 -> 4088700 | J8: =SUM(H8:I8) -> 41258700 | L8: 45917 | M8: 0 | N8: =J8-M8 -> 41258700 | P8: =J8-M8-N8 -> 0
A9: 45880 | B9: 2025/AMS/0104 | C9: PT. Allied Makmur Servis | F9: 25800000 | H9: =SUM(D9:G9) -> 25800000 | I9: =H9*0.11 -> 2838000 | J9: =SUM(H9:I9) -> 28638000 | L9: 45917 | N9: =J9-M9 -> 28638000 | P9: =J9-M9-N9 -> 0
A10: 45894 | B10: 250800601 | C10: PT. Makmur Meta Graha Dinamika | F10: 35664300 | H10: 32130000 | I10: =H10*0.11 -> 3534300 | J10: =SUM(H10:I10) -> 35664300 | L10: 45931 | N10: 35664300 | P10: =J10-M10-N10 -> 0
A11: 45894 | B11: 105/INV-S3/VIII-25 | C11: PT. Surya Semesta Sakti | F11: 166600000 | H11: =SUM(D11:G11) -> 166600000 | I11: =H11*0.11 -> 18326000 | J11: =SUM(H11:I11) -> 184926000 | L11: 45931 | N11: =J11-M11 -> 184926000 | P11: =J11-M11-N11 -> 0
A12: 45894 | B12: 188/Inv-asm/VIII/2025 | C12: CV. Aurora Sheet Metal | F12: 22560000 | H12: =SUM(D12:G12) -> 22560000 | I12: =H12*0.11 -> 2481600 | J12: =SUM(H12:I12) -> 25041600 | L12: 45895 | N12: =J12-M12 -> 25041600 | P12: =J12-M12-N12 -> 0
A13: 45896 | B13: SI-2508031 | C13: PT. Caprefindo | F13: 16800000 | H13: =SUM(D13:G13) -> 16800000 | I13: =H13*0.11 -> 1848000 | J13: =SUM(H13:I13) -> 18648000 | L13: 45931 | N13: =J13-M13 -> 18648000 | P13: =J13-M13-N13 -> 0
A14: 45896 | B14: 429/INV/IP/VIII/2025 | C14: PT. Indoporlen | F14: 375000000 | H14: =SUM(D14:G14) -> 375000000 | I14: =H14*0.11 -> 41250000 | J14: =SUM(H14:I14) -> 416250000 | L14: 45931 | N14: =J14-M14 -> 416250000 | P14: =J14-M14-N14 -> 0
A15: 45894 | B15: 56/J/VIII/25 | C15: PT. Jaya Refractorindo Utama | F15: 43000000 | H15: =SUM(D15:G15) -> 43000000 | I15: =H15*0.11 -> 4730000 | J15: =SUM(H15:I15) -> 47730000 | L15: 45894 | N15: =J15-M15 -> 47730000 | P15: =J15-M15-N15 -> 0
A16: 45894 | B16: 55/J/VIII/25 | C16: PT. Jaya Refractorindo Utama | F16: 39350000 | H16: =SUM(D16:G16) -> 39350000 | I16: =H16*0.11 -> 4328500 | J16: =SUM(H16:I16) -> 43678500 | L16: 45894 | N16: =J16-M16 -> 43678500 | P16: =J16-M16-N16 -> 0
H17: =SUM(D17:G17) -> 0 | I17: =H17*0.11 -> 0 | J17: =SUM(H17:I17) -> 0 | M17: 0 | N17: =J17 -> 0 | P17: =J17-M17-N17 -> 0 | U17: =#REF! -> #REF!
H18: =SUM(D18:G18) -> 0 | I18: =H18*0.11 -> 0 | J18: =SUM(H18:I18) -> 0 | M18: 0 | N18: =J18 -> 0 | P18: =J18-M18-N18 -> 0
C19: Total | D19: =SUM(D7:D18) -> 0 | E19: =SUM(E7:E18) -> 0 | F19: =SUM(F7:F18) -> 777944300 | G19: =SUM(G7:G18) -> 0 | H19: =SUM(H7:H18) -> 774410000 | I19: =SUM(I7:I18) -> 85185100 | J19: =SUM(J7:J18) -> 859595100 | M19: =SUM(M7:M18) -> 0 | N19: =SUM(N7:N18) -> 859595100 | P19: =SUM(P7:P18) -> 0 | R19: =SUM(R7:R18) -> 0 | S19: =SUM(S7:S18) -> 0 | U19: =SUM(U7:U18) -> #REF!
U20: =#REF!-U19 -> #REF!

Sheet INV SEPTEMBER
A1: Kewajiban GMT September 2025
A3: PPN
A5: Tanggal | B5: No. Invoice | C5: Supplier | D5: Keterangan | L5: Tgl Pembayaran | M5: Beban Admin | N5: Nilai Pembayaran | P5: Saldo AP
D6: Jasa | E6: Anchor | F6: Material | G6: Sewa Alat | H6: Total | I6: PPN | J6: Grand Total
A7: 45904 | B7: WIP/0999/T/IX/2025 | C7: PT. Willich Isolasi Pratama | F7: 8500000 | H7: =SUM(D7:G7) -> 8500000 | I7: =H7*0.11 -> 935000 | J7: =SUM(H7:I7) -> 9435000 | L7: 45904 | N7: =J7-M7 -> 9435000 | P7: =J7-M7-N7 -> 0
A8: 45912 | B8: 131/GMT/PO/IX/2025 | C8: CV. Putra Indra Boga | E8: 52046500 | H8: =SUM(D8:G8) -> 52046500 | I8: =H8*0.11 -> 5725115 | J8: =SUM(H8:I8) -> 57771615 | L8: 45912 | N8: =J8-M8 -> 57771615 | P8: =J8-M8-N8 -> 0
A9: 45917 | B9: SI-2509013 | C9: PT. Caprefindo | F9: 35000000 | H9: =SUM(D9:G9) -> 35000000 | I9: =H9*0.11 -> 3850000 | J9: =SUM(H9:I9) -> 38850000 | L9: 45945 | N9: =J9-M9 -> 38850000 | P9: =J9-M9-N9 -> 0
A10: 45917 | B10: 2037/IX2025/KLOTANGERANG/Q311 | C10: PT. Kawan Lama Solusi | F10: 30518875 | H10: =SUM(D10:G10) -> 30518875 | I10: =H10*0.11 -> 3357076.2 | J10: =SUM(H10:I10) -> 33875951 | L10: 45917 | N10: =J10-M10 -> 33875951 | P10: =J10-M10-N10 -> 0
A11: 45915 | B11: 250900263 | C11: PT. Makmur Meta Graha Dinamika | F11: 32130000 | H11: =SUM(D11:G11) -> 32130000 | I11: =H11*0.11 -> 3534300 | J11: =SUM(H11:I11) -> 35664300 | L11: 45945 | N11: =J11-M11 -> 35664300 | P11: =J11-M11-N11 -> 0
A12: 45915 | B12: 459/INV/IP/IX/2025 | C12: PT. Indoporlen | F12: 13870000 | H12: =SUM(D12:G12) -> 13870000 | I12: =H12*0.11 -> 1525700 | J12: =SUM(H12:I12) -> 15395700 | L12: 45945 | N12: =J12-M12 -> 15395700 | P12: =J12-M12-N12 -> 0
A13: 45915 | B13: 460/INV/IP/IX/2025 | C13: PT. Indoporlen | F13: 9900000 | H13: =SUM(D13:G13) -> 9900000 | I13: =H13*0.11 -> 1089000 | J13: =SUM(H13:I13) -> 10989000 | L13: 45945 | N13: =J13-M13 -> 10989000 | P13: =J13-M13-N13 -> 0
A14: 45923 | B14: 75/GMT/PO/IV/2025 | C14: Satria Purwanto | D14: 26600000 | H14: =SUM(D14:G14) -> 26600000 | I14: 0 | J14: =SUM(H14:I14) -> 26600000 | L14: 45931 | N14: =J14-M14 -> 26600000 | P14: =J14-M14-N14 -> 0
A15: 45923 | B15: N-021124134 | C15: PT. Afi Buana Prima | D15: 119000000 | H15: =SUM(D15:G15) -> 119000000 | I15: =H15*0.11 -> 13090000 | J15: =SUM(H15:I15) -> 132090000 | N15: 0 | P15: =J15-M15-N15 -> 132090000
A16: 45930 | C16: CV. Maha Jaya Packing | F16: 7700000 | H16: =SUM(D16:G16) -> 7700000 | I16: =H16*0.11 -> 847000 | J16: =SUM(H16:I16) -> 8547000 | L16: 45930 | N16: =J16-M16 -> 8547000 | P16: =J16-M16-N16 -> 0
H17: =SUM(D17:G17) -> 0 | I17: =H17*0.11 -> 0 | J17: =SUM(H17:I17) -> 0 | N17: 0 | P17: =J17-M17-N17 -> 0
H18: =SUM(D18:G18) -> 0 | I18: =H18*0.11 -> 0 | J18: =SUM(H18:I18) -> 0 | M18: 0 | N18: 0 | P18: =J18-M18-N18 -> 0
C19: Total | D19: =SUM(D7:D18) -> 145600000 | E19: =SUM(E7:E18) -> 52046500 | F19: =SUM(F7:F18) -> 137618875 | G19: =SUM(G7:G18) -> 0 | H19: =SUM(H7:H18) -> 335265375 | I19: =SUM(I7:I18) -> 33953191 | J19: =SUM(J7:J18) -> 3.6921857e+08 | M19: =SUM(M7:M18) -> 0 | N19: =SUM(N7:N18) -> 2.3712857e+08 | P19: =SUM(P7:P18) -> 132090000 | U19: =SUM(U7:U18) -> 0
U20: =#REF!-U19 -> #REF!
A23: Rek PT. Mula | B23: Mandiri | C23: 156-000-4145126
B24: A/n | C24: PT. Mitra Utama Lestari Abadi
A26: Rek PT Caprefindo | B26: BNI | C26: 001-625-4426
B27: A/n | C27: PT. Caprefindo

Sheet INV OKTOBER
A1: Kewajiban GMT Oktober 2025
A3: PPN
A4: Tanggal | B4: No. Invoice | C4: SUPPLIER | D4: Keterangan | L4: Tgl Pembayaran | M4: Potongan PPH 2% | N4: Nilai Pembayaran | P4: Saldo AR
D5: Jasa | E5: Anchor | F5: Material | G5: Sewa Alat | H5: Total | I5: PPN | J5: Grand Total
A6: 45932 | B6: SI-2509045 | C6: PT. Caprefindo | F6: 9150000 | H6: =SUM(D6:G6) -> 9150000 | I6: =H6*0.11 -> 1006500 | J6: =SUM(H6:I6) -> 10156500 | L6: 45978 | M6: 0 | N6: =J6-M6 -> 10156500 | P6: =J6-M6-N6 -> 0
A7: 45933 | B7: 0009/INV/09/25 | C7: PT. Indobricks Sejahtera | F7: 4000000 | H7: =SUM(D7:G7) -> 4000000 | I7: =H7*0.11 -> 440000 | J7: =SUM(H7:I7) -> 4440000 | L7: 45933 | M7: =D7*0.02 -> 0 | N7: =J7-M7 -> 4440000 | P7: =J7-M7-N7 -> 0
A8: 45931 | C8: Suwarso | D8: 1200000 | H8: =SUM(D8:G8) -> 1200000 | I8: 0 | J8: =SUM(H8:I8) -> 1200000 | L8: 45945 | M8: 0 | N8: =J8-M8 -> 1200000 | P8: =J8-M8-N8 -> 0
A9: 45943 | B9: 251000126 | C9: PT. Makmur Meta Graha Dinamika | F9: 369750000 | H9: =SUM(D9:G9) -> 369750000 | I9: =H9*0.11 -> 40672500 | J9: =SUM(H9:I9) -> 410422500 | L9: 45978 | M9: 0 | N9: =J9-M9 -> 410422500 | P9: =J9-M9-N9 -> 0 | U9: =M9 -> 0
A10: 45943 | B10: 2520465 | C10: PT. Shinagawa Refratech Perkasa | F10: 33075000 | H10: =SUM(D10:G10) -> 33075000 | I10: =H10*0.11 -> 3638250 | J10: =SUM(H10:I10) -> 36713250 | L10: 45989 | N10: =J10-M10 -> 36713250 | P10: =J10-M10-N10 -> 0
A11: 45943 | B11: 274/INV-ASM/X/2025 | C11: CV. Aurora Sheet Metal | F11: 13200000 | H11: =SUM(D11:G11) -> 13200000 | I11: =H11*0.11 -> 1452000 | J11: =SUM(H11:I11) -> 14652000 | L11: 45943 | N11: =J11-M11 -> 14652000 | P11: =J11-M11-N11 -> 0
A12: 45943 | B12: 271/INV-ASM/X/2025 | C12: CV. Aurora Sheet Metal | F12: 2200000 | H12: =SUM(D12:G12) -> 2200000 | I12: =H12*0.11 -> 242000 | J12: =SUM(H12:I12) -> 2442000 | L12: 45943 | N12: =J12-M12 -> 2442000 | P12: =J12-M12-N12 -> 0
A13: 45944 | B13: 3259000835 | C13: PT. Indoporlen | F13: 15600000 | H13: =SUM(D13:G13) -> 15600000 | I13: =H13*0.11 -> 1716000 | J13: =SUM(H13:I13) -> 17316000 | L13: 45978 | N13: =J13-M13 -> 17316000 | P13: =J13-M13-N13 -> 0
A14: 45946 | B14: SI-2510014 | C14: PT. Caprefindo | F14: 34925000 | H14: =SUM(D14:G14) -> 34925000 | I14: =H14*0.11 -> 3841750 | J14: =SUM(H14:I14) -> 38766750 | L14: 45989 | N14: =J14-M14 -> 38766750 | P14: =J14-M14-N14 -> 0
A15: 45961 | B15: WM-0302/PR/X/2025-INV | C15: PT. Tyotech Mandiri Jaya | F15: 2940000 | H15: =SUM(D15:G15) -> 2940000 | I15: =H15*0.11 -> 323400 | J15: =SUM(H15:I15) -> 3263400 | L15: 45961 | N15: =J15-M15 -> 3263400 | P15: =J15-M15-N15 -> 0
A16: 45961 | B16: 2520500 | C16: PT. Shinagawa Refratech Perkasa | F16: 28212500 | H16: =SUM(D16:G16) -> 28212500 | I16: =H16*0.11 -> 3103375 | J16: =SUM(H16:I16) -> 31315875 | L16: 45989 | N16: =J16-M16 -> 31315875 | P16: =J16-M16-N16 -> 0
A17: 45961 | B17: 585/Inv/IP/X/2025 | C17: PT. Indoporlen | F17: 400000 | H17: =SUM(D17:G17) -> 400000 | I17: =H17*0.11 -> 44000 | J17: =SUM(H17:I17) -> 444000 | L17: 45989 | M17: 0 | N17: =J17-M17 -> 444000 | P17: =J17-M17-N17 -> 0
A18: 45961 | B18: 584/INV/IP/X/2025 | C18: PT. Indoporlen | F18: 14000000 | H18: =SUM(D18:G18) -> 14000000 | I18: =H18*0.11 -> 1540000 | J18: =SUM(H18:I18) -> 15540000 | L18: 45989 | N18: =J18-M18 -> 15540000 | P18: =J18-M18-N18 -> 0
H19: =SUM(D19:G19) -> 0 | I19: =H19*0.11 -> 0 | J19: =SUM(H19:I19) -> 0 | N19: 0 | P19: =J19-M19-N19 -> 0
H20: =SUM(D20:G20) -> 0 | I20: =H20*0.11 -> 0 | J20: =SUM(H20:I20) -> 0 | N20: 0 | P20: =J20-M20-N20 -> 0
H21: =SUM(D21:G21) -> 0 | I21: =H21*0.11 -> 0 | J21: =SUM(H21:I21) -> 0 | N21: 0 | P21: =J21-M21-N21 -> 0
H22: =SUM(D22:G22) -> 0 | I22: =H22*0.11 -> 0 | J22: =SUM(H22:I22) -> 0 | N22: =J22-M22 -> 0 | P22: =J22-M22-N22 -> 0
H23: =SUM(D23:G23) -> 0 | I23: =H23*0.11 -> 0 | J23: =SUM(H23:I23) -> 0 | N23: =J23-M23 -> 0 | P23: =J23-M23-N23 -> 0
H24: =SUM(D24:G24) -> 0 | I24: =H24*0.11 -> 0 | J24: =SUM(H24:I24) -> 0 | N24: =J24-M24 -> 0 | P24: =J24-M24-N24 -> 0
H25: =SUM(D25:G25) -> 0 | I25: =H25*0.11 -> 0 | J25: =SUM(H25:I25) -> 0 | N25: =J25-M25 -> 0 | P25: =J25-M25-N25 -> 0
H26: =SUM(D26:G26) -> 0 | I26: =H26*0.11 -> 0 | J26: =SUM(H26:I26) -> 0 | N26: =J26-M26 -> 0 | P26: =J26-M26-N26 -> 0
H27: =SUM(D27:G27) -> 0 | I27: =H27*0.11 -> 0 | J27: =SUM(H27:I27) -> 0 | M27: 0 | N27: =J27-M27 -> 0
C28: Total | D28: =SUM(D6:D27) -> 1200000 | E28: =SUM(E6:E27) -> 0 | F28: =SUM(F6:F27) -> 527452500 | G28: =SUM(G6:G27) -> 0 | H28: =SUM(H6:H27) -> 528652500 | I28: =SUM(I6:I27) -> 58019775 | J28: =SUM(J6:J27) -> 586672275 | M28: =SUM(M6:M27) -> 0 | N28: =SUM(N6:N27) -> 586672275 | P28: =SUM(P6:P27) -> 0 | U28: =SUM(U6:U27) -> 0
U29: =M28-U28 -> 0

Sheet INV NOVEMBER
A1: Kewajiban GMT November 2025
A3: PPN
A4: Tanggal | B4: No. Invoice | C4: Supplier | D4: Keterangan | L4: Tgl Pembayaran | M4: Potongan PPH 2% | N4: Nilai Pembayaran | P4: Saldo AP
D5: Jasa | E5: Anchor | F5: Material | G5: Sewa Alat | H5: Total | I5: PPN | J5: Grand Total
A6: 45972 | B6: WIP/1085/T/IX/2025 | C6: PT. Willich Isolasi Pratama | F6: 425000 | H6: =SUM(D6:G6) -> 425000 | I6: =H6*0.11 -> 46750 | J6: =H6+I6 -> 471750 | L6: 45972 | M6: =D6*0.02 -> 0 | N6: =J6-M6 -> 471750 | P6: =J6-M6-N6 -> 0
A7: 45972 | B7: 595/INV/IP/X/2025 | C7: PT. Indoporlen | F7: 143400000 | H7: =SUM(D7:G7) -> 143400000 | I7: =H7*0.11 -> 15774000 | J7: =H7+I7 -> 159174000 | L7: 45989 | M7: 0 | N7: =J7-M7 -> 159174000 | P7: =J7-M7-N7 -> 0
A8: 45972 | B8: 1055/INV-MES/XI/25 | C8: PT. Mega Eka Satya | D8: 2829093.9 | F8: =16031531.1-1886062.5 -> 14145469 | H8: =SUM(D8:G8) -> 16974562 | I8: =H8*0.11 -> 1867201.9 | J8: =H8+I8 -> 18841764 | L8: 45978 | M8: 0 | N8: =J8-M8 -> 18841764 | P8: =J8-M8-N8 -> 0
A9: 45972 | B9: 2025/AMS/0151 | C9: PT. Allied Makmur Servis | F9: 29905000 | H9: =SUM(D9:G9) -> 29905000 | I9: =H9*0.11 -> 3289550 | J9: =H9+I9 -> 33194550 | L9: 45989 | N9: =J9-M9 -> 33194550 | P9: =J9-M9-N9 -> 0
A10: 45979 | B10: 1055P/INV-MES/XI/25 | C10: PT. Mega Eka Satya | D10: 39607312 | H10: =SUM(D10:G10) -> 39607312 | I10: =H10*0.11 -> 4356804.4 | J10: =H10+I10 -> 43964117 | M10: 0 | N10: 0 | P10: =J10-M10-N10 -> 43964117
A11: 45979 | B11: 103/INV-DELINTEK/XI/2025 | C11: PT. Dele Indah Teknindo | E11: 32985000 | H11: =SUM(D11:G11) -> 32985000 | I11: =H11*0.11 -> 3628350 | J11: =H11+I11 -> 36613350 | L11: 46003 | N11: =J11-M11 -> 36613350 | P11: =J11-M11-N11 -> 0
A12: 45980 | B12: 328/INV-ASM/X/2025 | C12: CV. Aurora Sheet Metal | D12: 5500000 | H12: =SUM(D12:G12) -> 5500000 | I12: 0 | J12: =H12+I12 -> 5500000 | L12: 45980 | M12: 0 | N12: =J12-M12 -> 5500000 | P12: =J12-M12-N12 -> 0
A13: 45986 | B13: 1687/INV-MULA/XI-25 | C13: PT. Mitra Utama Lestari Abadi | F13: 20000000 | H13: =SUM(D13:G13) -> 20000000 | I13: =H13*0.11 -> 2200000 | J13: =H13+I13 -> 22200000 | N13: 0 | P13: =J13-M13-N13 -> 22200000
A14: 45987 | B14: SI-2511016 | C14: PT. Caprefindo | F14: 34000000 | H14: =SUM(D14:G14) -> 34000000 | I14: =H14*0.11 -> 3740000 | J14: =H14+I14 -> 37740000 | N14: 0 | P14: =J14-M14-N14 -> 37740000
A15: 45989 | B15: 251100801 | C15: PT. Makmur Meta Graha Dinamika | F15: 126480000 | H15: =SUM(D15:G15) -> 126480000 | I15: =H15*0.11 -> 13912800 | J15: =H15+I15 -> 140392800 | N15: 0 | P15: =J15-M15-N15 -> 140392800
A16: 45989 | B16: 251100957 | C16: PT. Makmur Meta Graha Dinamika | F16: 364000000 | H16: =SUM(D16:G16) -> 364000000 | I16: =H16*0.11 -> 40040000 | J16: =H16+I16 -> 404040000 | N16: 0 | P16: =J16-M16-N16 -> 404040000
A17: 45989 | B17: WIP/373/PRF/IX/2025 | C17: PT. Willich Isolasi Pratama | F17: 144000000 | H17: =SUM(D17:G17) -> 144000000 | I17: =H17*0.11 -> 15840000 | J17: =H17+I17 -> 159840000 | N17: 0 | P17: =J17-M17-N17 -> 159840000
H18: =SUM(D18:G18) -> 0 | I18: =H18*0.11 -> 0 | J18: =H18+I18 -> 0 | N18: 0 | P18: =J18-M18-N18 -> 0
H19: =SUM(D19:G19) -> 0 | I19: =H19*0.11 -> 0 | J19: =H19+I19 -> 0 | N19: 0 | P19: =J19-M19-N19 -> 0
H20: =SUM(D20:G20) -> 0 | I20: 0 | J20: =H20+I20 -> 0 | N20: =J20-M20 -> 0 | P20: =J20-M20-N20 -> 0
H21: =SUM(D21:G21) -> 0 | I21: =H21*0.11 -> 0 | J21: =H21+I21 -> 0 | N21: =J21-M21 -> 0 | P21: =J21-M21-N21 -> 0
H22: =SUM(D22:G22) -> 0 | I22: =H22*0.11 -> 0 | J22: =H22+I22 -> 0 | N22: 0 | P22: =J22-M22-N22 -> 0
H23: =SUM(D23:G23) -> 0 | I23: =H23*0.11 -> 0 | J23: =H23+I23 -> 0 | N23: 0 | P23: =J23-M23-N23 -> 0
H24: =SUM(D24:G24) -> 0 | I24: =H24*0.11 -> 0 | J24: =H24+I24 -> 0 | N24: =J24-M24 -> 0 | P24: =J24-M24-N24 -> 0
H25: =SUM(D25:G25) -> 0 | I25: =H25*0.11 -> 0 | J25: =H25+I25 -> 0 | N25: =J25-M25 -> 0 | P25: =J25-M25-N25 -> 0
H26: =SUM(D26:G26) -> 0 | I26: =H26*0.11 -> 0 | J26: =H26+I26 -> 0 | N26: =J26-M26 -> 0 | P26: =J26-M26-N26 -> 0
H27: =SUM(D27:G27) -> 0 | I27: =H27*0.11 -> 0 | J27: =H27+I27 -> 0 | N27: =J27-M27 -> 0 | P27: =J27-M27-N27 -> 0
H28: =SUM(D28:G28) -> 0 | I28: =H28*0.11 -> 0 | J28: =H28+I28 -> 0 | N28: =J28-M28 -> 0 | P28: =J28-M28-N28 -> 0
C29: Total | D29: =SUM(D6:D28) -> 47936406 | E29: =SUM(E6:E28) -> 32985000 | F29: =SUM(F6:F28) -> 8.7635547e+08 | G29: =SUM(G6:G28) -> 0 | H29: =SUM(H6:H28) -> 957276875 | I29: =SUM(I6:I28) -> 1.0469546e+08 | J29: =SUM(J6:J28) -> 1.0619723e+09 | M29: =SUM(M6:M28) -> 0 | N29: =SUM(N6:N28) -> 2.5379541e+08 | P29: =SUM(P6:P28) -> 8.0817692e+08 | U29: =SUM(U6:U28) -> 0
U30: =M29-U29 -> 0
G34: =800*600 -> 480000
G35: =G34*0.3 -> 144000
G36: =G34-G35 -> 336000

Sheet INV DESEMBER
A1: Kewajiban GMT Desember 2025
A3: PPN
A4: Tanggal | B4: No. Invoice | C4: Supplier | D4: Keterangan | L4: Tgl Pembayaran | M4: Potongan PPH 2% | N4: Nilai Pembayaran | P4: Saldo AP
D5: Jasa | E5: Anchor | F5: Material | G5: Sewa Alat | H5: Total | I5: PPN | J5: Grand Total
A6: 45992 | B6: 2025/0117 | C6: PT. Kelola Buana Lestari | D6: 81900000 | H6: =SUM(D6:G6) -> 81900000 | I6: =H6*0.11 -> 9009000 | J6: =H6+I6 -> 90909000 | L6: 46003 | N6: =J6-M6 -> 90909000 | P6: =J6-N6 -> 0
A7: 45994 | B7: 3259001014 | C7: PT. Indoporlen | F7: 1426110000 | H7: =SUM(D7:G7) -> 1426110000 | I7: =H7*0.11 -> 156872100 | J7: =H7+I7 -> 1582982100 | N7: 0 | P7: =J7-N7 -> 1582982100
A8: 45995 | B8: 3259001005 | C8: PT. Indoporlen | F8: 1426110000 | H8: =SUM(D8:G8) -> 1426110000 | I8: =H8*0.11 -> 156872100 | J8: =H8+I8 -> 1582982100 | N8: 0 | P8: =J8-N8 -> 1582982100
A9: 45999 | B9: 620/INV/IP/XII/2025 | C9: PT. Indoporlen | F9: 170000000 | H9: =SUM(D9:G9) -> 170000000 | I9: =H9*0.11 -> 18700000 | J9: =H9+I9 -> 188700000 | N9: 0 | P9: =J9-N9 -> 188700000
A10: 45999 | B10: 251200020 | C10: PT. Makmur Meta Graha Dinamika | F10: 32130000 | H10: =SUM(D10:G10) -> 32130000 | I10: =H10*0.11 -> 3534300 | J10: =H10+I10 -> 35664300 | N10: 0 | P10: =J10-N10 -> 35664300
A11: 45999 | B11: SI-2512002 | C11: PT. Caprefindo | F11: 3150000 | H11: =SUM(D11:G11) -> 3150000 | I11: =H11*0.11 -> 346500 | J11: =H11+I11 -> 3496500 | N11: 0 | P11: =J11-N11 -> 3496500
A12: 46001 | B12: 626/INV/IP/XII/2025 | C12: PT. Indoporlen | F12: 30000000 | H12: =SUM(D12:G12) -> 30000000 | I12: =H12*0.11 -> 3300000 | J12: =H12+I12 -> 33300000 | N12: 0 | P12: =J12-N12 -> 33300000
A13: 46001 | B13: 625/INV/IP/XII/2025 | C13: PT. Indoporlen | F13: 13870000 | H13: =SUM(D13:G13) -> 13870000 | I13: =H13*0.11 -> 1525700 | J13: =H13+I13 -> 15395700 | N13: 0 | P13: =J13-N13 -> 15395700
A14: 46001 | B14: 631/INV/IP/XII/2025 | C14: PT. Indoporlen | F14: 45000000 | H14: =SUM(D14:G14) -> 45000000 | I14: =H14*0.11 -> 4950000 | J14: =H14+I14 -> 49950000 | N14: 0 | P14: =J14-N14 -> 49950000
A15: 46001 | B15: 16/PUT/XII-2025 | C15: CV. Panca Utama Teknik | D15: 10000000 | H15: =SUM(D15:G15) -> 10000000 | I15: =H15*0.11 -> 1100000 | J15: =H15+I15 -> 11100000 | L15: 46003 | N15: =J15-M15 -> 11100000 | P15: =J15-N15 -> 0
A16: 46003 | B16: 2025/AMS/0187 | C16: PT. Allied Makmur Servis | F16: 14952500 | H16: =SUM(D16:G16) -> 14952500 | I16: =H16*0.11 -> 1644775 | J16: =H16+I16 -> 16597275 | N16: 0 | P16: =J16-N16 -> 16597275
A17: 46006 | B17: WIP/1378/T/XI/2025 | C17: PT. Willich Isolasi Pratama | F17: 8500000 | H17: =SUM(D17:G17) -> 8500000 | I17: =H17*0.11 -> 935000 | J17: =H17+I17 -> 9435000 | L17: 45989 | N17: =J17-M17 -> 9435000 | P17: =J17-N17 -> 0
A18: 46006 | B18: WIP/1377/T/XI/2025 | C18: PT. Willich Isolasi Pratama | F18: 8500000 | H18: =SUM(D18:G18) -> 8500000 | I18: =H18*0.11 -> 935000 | J18: =H18+I18 -> 9435000 | L18: 45989 | N18: =J18-M18 -> 9435000 | P18: =J18-N18 -> 0
A19: 46006 | B19: 177-12-25-GTP | C19: PT. Akurasi Presisi Indonesia | E19: 12000000 | H19: =SUM(D19:G19) -> 12000000 | I19: =H19*0.11 -> 1320000 | J19: =H19+I19 -> 13320000 | N19: 0 | P19: =J19-N19 -> 13320000
H20: =SUM(D20:G20) -> 0 | I20: =H20*0.11 -> 0 | J20: =H20+I20 -> 0 | N20: 0 | P20: =J20-N20 -> 0
H21: =SUM(D21:G21) -> 0 | I21: 0 | J21: =H21+I21 -> 0 | N21: 0 | P21: =J21-N21 -> 0
H22: =SUM(D22:G22) -> 0 | I22: 0 | J22: =H22+I22 -> 0 | N22: 0 | P22: =J22-N22 -> 0
H23: =SUM(D23:G23) -> 0 | I23: =H23*0.11 -> 0 | J23: =H23+I23 -> 0 | N23: 0 | P23: =J23-N23 -> 0
H24: =SUM(D24:G24) -> 0 | I24: =H24*0.11 -> 0 | J24: =H24+I24 -> 0 | N24: 0 | P24: =J24-N24 -> 0
H25: =SUM(D25:G25) -> 0 | I25: =H25*0.11 -> 0 | J25: =H25+I25 -> 0 | N25: =J25-M25 -> 0 | P25: =J25-N25 -> 0
H26: =SUM(D26:G26) -> 0 | I26: =H26*0.11 -> 0 | J26: =H26+I26 -> 0 | N26: =J26-M26 -> 0 | P26: =J26-N26 -> 0
H27: =SUM(D27:G27) -> 0 | I27: =H27*0.11 -> 0 | J27: =H27+I27 -> 0 | N27: =J27-M27 -> 0 | P27: =J27-N27 -> 0
H28: =SUM(D28:G28) -> 0 | I28: =H28*0.11 -> 0 | J28: =H28+I28 -> 0 | N28: =J28-M28 -> 0 | P28: =J28-N28 -> 0
H29: =SUM(D29:G29) -> 0 | I29: =H29*0.11 -> 0 | J29: =H29+I29 -> 0 | N29: =J29-M29 -> 0 | P29: =J29-N29 -> 0
H30: =SUM(D30:G30) -> 0 | I30: =H30*0.11 -> 0 | J30: =H30+I30 -> 0 | N30: =J30-M30 -> 0 | P30: =J30-N30 -> 0
H31: =SUM(D31:G31) -> 0 | I31: =H31*0.11 -> 0 | J31: =H31+I31 -> 0 | M31: 0 | N31: 0 | P31: =J31-N31 -> 0
H32: =SUM(D32:G32) -> 0 | I32: =H32*0.11 -> 0 | J32: =H32+I32 -> 0 | M32: =D32*0.02 -> 0 | N32: 0 | P32: =J32-N32 -> 0
H33: =SUM(D33:G33) -> 0 | I33: =H33*0.11 -> 0 | J33: =H33+I33 -> 0 | M33: =D33*0.02 -> 0 | N33: 0 | P33: =J33-N33 -> 0
H34: =SUM(D34:G34) -> 0 | I34: =H34*0.11 -> 0 | J34: =H34+I34 -> 0 | N34: 0 | P34: =J34-N34 -> 0
H35: =SUM(D35:G35) -> 0 | I35: =H35*0.11 -> 0 | J35: =H35+I35 -> 0 | N35: 0 | P35: =J35-N35 -> 0
H36: =SUM(D36:G36) -> 0 | I36: =H36*0.11 -> 0 | J36: =H36+I36 -> 0 | N36: 0 | P36: =J36-N36 -> 0
H37: =SUM(D37:G37) -> 0 | I37: =H37*0.11 -> 0 | J37: =H37+I37 -> 0 | M37: 0 | N37: =J37-M37 -> 0 | P37: =J37-N37 -> 0
C38: Total | D38: =SUM(D6:D37) -> 91900000 | E38: =SUM(E6:E37) -> 12000000 | F38: =SUM(F6:F37) -> 3178322500 | G38: =SUM(G6:G37) -> 0 | H38: =SUM(H6:H37) -> 3282222500 | I38: =SUM(I6:I37) -> 361044475 | J38: =SUM(J6:J37) -> 3643266975 | M38: =SUM(M6:M37) -> 0 | N38: =SUM(N6:N37) -> 120879000 | P38: =SUM(P6:P37) -> 3522387975
