Workbook

Sheet REKAP SALES
B1: PT. GEMA TEKNIK PERKASA
B2: REKAP DATA SALES PPN
B3: TAHUN 2025
B5: No | C5: Periode | D5: Keterangan
D6: Jasa | E6: Anchor | F6: Material | G6: Sewa Alat | H6: Total
B8: 1 | C8: JANUARI | D8: ='INV JANUARI'!D34 -> 1106775000 | E8: ='INV JANUARI'!E34 -> 160937500 | F8: ='INV JANUARI'!F34 -> 2716640034 | G8: ='INV JANUARI'!G34 -> 0 | H8: =SUM(D8:G8) -> 3984352534
B9: 2 | C9: FEBRUARI | D9: ='INV FEBRUARI'!D32 -> 243575000 | E9: ='INV FEBRUARI'!E32 -> 204059993 | F9: ='INV FEBRUARI'!F32 -> 441168525 | G9: ='INV FEBRUARI'!G32 -> 272100000 | H9: =SUM(D9:G9) -> 1160903518
B10: 3 | C10: MARET | D10: ='INV MARET'!D26 -> 283720000 | E10: ='INV MARET'!E26 -> 251056000 | F10: ='INV MARET'!F26 -> 2936455000 | G10: ='INV MARET'!G26 -> 0 | H10: =SUM(D10:G10) -> 3471231000
B11: 4 | C11: APRIL | D11: ='INV APRIL'!D54 -> 1306533000 | E11: ='INV APRIL'!E54 -> 304829500 | F11: ='INV APRIL'!F54 -> 1093257330 | G11: ='INV APRIL'!G54 -> 310300000 | H11: =SUM(D11:G11) -> 3014919830
B12: 5 | C12: MEI | D12: ='INV MEI'!D23 -> 1011453350 | E12: ='INV MEI'!E23 -> 235111850 | F12: ='INV MEI'!F23 -> 323524520 | G12: ='INV MEI'!G23 -> 0 | H12: =SUM(D12:G12) -> 1570089720
B13: 6 | C13: JUNI | D13: ='INV JUNI'!D24 -> 40125000 | E13: ='INV JUNI'!E24 -> 146923500 | F13: ='INV JUNI'!F24 -> 158923300 | G13: ='INV JUNI'!G24 -> 0 | H13: =SUM(D13:G13) -> 345971800
B14: 7 | C14: JULI | D14: ='INV JULI'!D31 -> 80262000 | E14: ='INV JULI'!E31 -> 461667500 | F14: ='INV JULI'!F31 -> 724983000 | G14: ='INV JULI'!G31 -> 0 | H14: =SUM(D14:G14) -> 1266912500
B15: 8 | C15: AGUSTUS | D15: ='INV AGUSTUS'!D34 -> 449900000 | E15: ='INV AGUSTUS'!E34 -> 386631606 | F15: ='INV AGUSTUS'!F34 -> 1103267500 | G15: ='INV AGUSTUS'!G34 -> 0 | H15: =SUM(D15:G15) -> 1939799106
B16: 9 | C16: SEPTEMBER | D16: ='INV SEPTEMBER'!D31 -> 449300000 | E16: ='INV SEPTEMBER'!E31 -> 416661800 | F16: ='INV SEPTEMBER'!F31 -> 190025000 | G16: ='INV SEPTEMBER'!G31 -> 1200000 | H16: =SUM(D16:G16) -> 1057186800
B17: 10 | C17: OKTOBER | D17: ='INV OKTOBER'!D31 -> 257290000 | E17: ='INV OKTOBER'!E31 -> 253599150 | F17: ='INV OKTOBER'!F31 -> 849685000 | G17: ='INV OKTOBER'!G31 -> 0 | H17: =SUM(D17:G17) -> 1360574150
B18: 11 | C18: NOVEMBER | D18: ='INV NOVEMBER'!D34 -> 992127000 | E18: ='INV NOVEMBER'!E34 -> 801065400 | F18: ='INV NOVEMBER'!F34 -> 1580805000 | G18: ='INV NOVEMBER'!G34 -> 0 | H18: =SUM(D18:G18) -> 3373997400
B19: 12 | C19: DESEMBER | D19: ='INV DESEMBER'!D55 -> 385600000 | E19: ='INV DESEMBER'!E55 -> 175061750 | F19: ='INV DESEMBER'!F55 -> 5887625313 | G19: ='INV DESEMBER'!G55 -> 0 | H19: =SUM(D19:G19) -> 6448287063 | J19: 27922575488 | K19: SALES 2023
C20: TOTAL | D20: =SUM(D8:D19) -> 6606660350 | E20: =SUM(E8:E19) -> 3797605549 | F20: =SUM(F8:F19) -> 18006359522 | G20: =SUM(G8:G19) -> 583600000 | H20: =SUM(H8:H19) -> 28994225421 | I20: =H20/12 -> 2.4161855e+09
J21: =H20-J19 -> 1071649933
H22: 22793972902 | I22: SALES 2024 | J22: =J21/H20*100 -> 3.6960806
H24: =H20-H22 -> 6200252519
H25: =H24/H22*100 -> 27.201281

Sheet INV JANUARI
A1: Piutang GMT Januari 2025
A4: PPN
A5: Tanggal | B5: No. Invoice | C5: Customer | D5: Keterangan | L5: Tgl Pembayaran | M5: Potongan PPH 2% | N5: Nilai Pembayaran | P5: Saldo AR
D6: Jasa | E6: Anchor | F6: Material | G6: Sewa Alat | H6: Total | I6: PPN | J6: Grand Total
A7: 45660 | B7: 01/TAG/GMT/I/2025 | C7: PT. Gemilang MitraAbadi Sejahtera | E7: 1975000 | H7: =SUM(D7:G7) -> 1975000 | I7: =H7*0.11 -> 217250 | J7: =H7+I7 -> 2192250 | L7: 45670 | N7: =J7-M7 -> 2192250 | P7: =J7-M7-N7 -> 0
A8: 45663 | B8: 02/TAG/GMT/I/2025 | C8: PT. Bumi Alam Segar | D8: 55000000 | H8: =SUM(D8:G8) -> 55000000 | I8: =H8*0.11 -> 6050000 | J8: =H8+I8 -> 61050000 | L8: 45698 | M8: 1008333 | N8: =J8-M8 -> 60041667 | P8: =J8-M8-N8 -> 0 | Q8: 60041667
A9: 45666 | B9: 03/TAG/GMT/I/2025 | C9: PT. Daiki Aluminium Industry Indonesia | F9: 1275000 | H9: =SUM(D9:G9) -> 1275000 | I9: =H9*0.11 -> 140250 | J9: =H9+I9 -> 1415250 | L9: 45705 | N9: =J9-M9 -> 1415250 | P9: =J9-M9-N9 -> 0 | Q9: =J8-Q8 -> 1008333
A10: 45666 | B10: 04/TAG/GMT/I/2025 | C10: PT. Daiki Aluminium Industry Indonesia | D10: 52900000 | H10: =SUM(D10:G10) -> 52900000 | I10: =H10*0.11 -> 5819000 | J10: =H10+I10 -> 58719000 | L10: 45705 | M10: =D10*0.02 -> 1058000 | N10: =J10-M10 -> 57661000 | P10: =J10-M10-N10 -> 0
A11: 45666 | B11: 05/TAG/GMT/I/2025 | C11: PT. Daiki Aluminium Industry Indonesia | D11: 224400000 | H11: =SUM(D11:G11) -> 224400000 | I11: =H11*0.11 -> 24684000 | J11: =H11+I11 -> 249084000 | L11: 45705 | M11: =D11*0.02 -> 4488000 | N11: =J11-M11 -> 244596000 | P11: =J11-M11-N11 -> 0 | Q11: =SUM(P9:P17) -> 0
A12: 45666 | B12: 06/TAG/GMT/I/2025 | C12: PT. Daiki Aluminium Industry Indonesia | D12: 149000000 | H12: =SUM(D12:G12) -> 149000000 | I12: =H12*0.11 -> 16390000 | J12: =H12+I12 -> 165390000 | L12: 45705 | M12: =D12*0.02 -> 2980000 | N12: =J12-M12 -> 162410000 | P12: =J12-M12-N12 -> 0 | Q12: =P19 -> 0
A13: 45666 | B13: 07/TAG/GMT/I/2025 | C13: PT. Daiki Aluminium Industry Indonesia | D13: 94700000 | H13: =SUM(D13:G13) -> 94700000 | I13: =H13*0.11 -> 10417000 | J13: =H13+I13 -> 105117000 | L13: 45705 | M13: =D13*0.02 -> 1894000 | N13: =J13-M13 -> 103223000 | P13: =J13-M13-N13 -> 0 | Q13: =SUM(Q11:Q12) -> 0
A14: 45666 | B14: 08/TAG/GMT/I/2025 | C14: PT. Daiki Aluminium Industry Indonesia | D14: 205400000 | H14: =SUM(D14:G14) -> 205400000 | I14: =H14*0.11 -> 22594000 | J14: =H14+I14 -> 227994000 | L14: 45705 | M14: =D14*0.02 -> 4108000 | N14: =J14-M14 -> 223886000 | P14: =J14-M14-N14 -> 0 | Q14: 1112410084
A15: 45666 | B15: 09/TAG/GMT/I/2025 | C15: PT. Daiki Aluminium Industry Indonesia | D15: 66975000 | H15: =SUM(D15:G15) -> 66975000 | I15: =H15*0.11 -> 7367250 | J15: =H15+I15 -> 74342250 | L15: 45705 | M15: =D15*0.02 -> 1339500 | N15: =J15-M15 -> 73002750 | P15: =J15-M15-N15 -> 0 | Q15: =Q13-Q14 -> -1112410084
A16: 45666 | B16: 10/TAG/GMT/I/2025 | C16: PT. Daiki Aluminium Industry Indonesia | D16: 155000000 | H16: =SUM(D16:G16) -> 155000000 | I16: =H16*0.11 -> 17050000 | J16: =H16+I16 -> 172050000 | L16: 45705 | M16: =D16*0.02 -> 3100000 | N16: =J16-M16 -> 168950000 | P16: =J16-M16-N16 -> 0 | U16: =M16 -> 3100000
A17: 45666 | B17: 11/TAG/GMT/I/2025 | C17: PT. Daiki Aluminium Industry Indonesia | D17: 66900000 | H17: =SUM(D17:G17) -> 66900000 | I17: =H17*0.11 -> 7359000 | J17: =H17+I17 -> 74259000 | L17: 45705 | M17: =D17*0.02 -> 1338000 | N17: =J17-M17 -> 72921000 | P17: =J17-M17-N17 -> 0
A18: 45666 | B18: 12/TAG/GMT/I/2025 | C18: PT. Eagle Industry Indonesia | F18: 35625000 | H18: =SUM(D18:G18) -> 35625000 | I18: =H18*0.11 -> 3918750 | J18: =H18+I18 -> 39543750 | L18: 45702 | N18: =J18-M18 -> 39543750 | P18: =J18-M18-N18 -> 0
A19: 45673 | B19: 13/TAG/GMT/I/2025 | C19: PT. Daiki Aluminium Industry Indonesia | F19: 3200000 | H19: =SUM(D19:G19) -> 3200000 | I19: =H19*0.11 -> 352000 | J19: =H19+I19 -> 3552000 | L19: 45705 | N19: =J19-M19 -> 3552000 | P19: =J19-M19-N19 -> 0
A20: 45673 | B20: 14/TAG/GMT/I/2025 | C20: PT. Santos Jaya Abadi | F20: 2500000 | H20: =SUM(D20:G20) -> 2500000 | I20: =H20*0.11 -> 275000 | J20: =H20+I20 -> 2775000 | L20: 45687 | N20: =J20-M20 -> 2775000 | P20: =J20-M20-N20 -> 0
A21: 45673 | B21: 15/TAG/GMT/I/2025 | C21: PT. Shinagawa Refratech Perkasa | D21: 36500000 | H21: =SUM(D21:G21) -> 36500000 | I21: =H21*0.11 -> 4015000 | J21: =H21+I21 -> 40515000 | L21: 45713 | M21: =(D21*0.02)+2000 -> 732000 | N21: =J21-M21 -> 39783000 | P21: =J21-M21-N21 -> 0
A22: 45677 | B22: 16/TAG/GMT/I/2025 | C22: PT. Sriwijaya Alam Segar | F22: 6350000 | H22: =SUM(D22:G22) -> 6350000 | I22: =H22*0.11 -> 698500 | J22: =H22+I22 -> 7048500 | L22: 45708 | N22: =J22-M22 -> 7048500 | P22: =J22-M22-N22 -> 0
A23: 45680 | B23: 17/TAG/GMT/I/2025 | C23: PT. Kopsri | F23: 833162750 | H23: =SUM(D23:G23) -> 833162750 | I23: =H23*0.11 -> 91647902 | J23: =H23+I23 -> 9.2481065e+08 | L23: 45866 | N23: =(200000000+150000000+300000000)+49808153+60000000+30000000 -> 789808153 | P23: =J23-M23-N23 -> 1.350025e+08
A24: 45677 | B24: 18/TAG/GMT/I/2025 | C24: PT. Srijasa Brika Perkasa | E24: 3990000 | F24: 3291750 | H24: =SUM(D24:G24) -> 7281750 | I24: =H24*0.11 -> 800992.5 | J24: =H24+I24 -> 8082742.5 | L24: 45714 | N24: =J24-M24 -> 8082742.5 | P24: =J24-M24-N24 -> 0
A25: 45679 | B25: 19/TAG/GMT/I/2025 | C25: PT. Nusantara Tehnik Indonesia | F25: 9600000 | H25: =SUM(D25:G25) -> 9600000 | I25: =H25*0.11 -> 1056000 | J25: =H25+I25 -> 10656000 | L25: 45777 | N25: =J25-M25 -> 10656000 | P25: =J25-M25-N25 -> 0
A26: 45679 | B26: 20/TAG/GMT/I/2025 | C26: PT. Gunung Api Mulia | E26: 44362500 | H26: =SUM(D26:G26) -> 44362500 | I26: =H26*0.11 -> 4879875 | J26: =H26+I26 -> 49242375 | L26: 45693 | N26: =J26-M26 -> 49242375 | P26: =J26-M26-N26 -> 0
A27: 45680 | B27: 21/TAG/GMT/I/2025 | C27: PT. Srijasa Brika Perkasa | F27: 1796854784 | H27: =SUM(D27:G27) -> 1796854784 | I27: =H27*0.11 -> 1.9765403e+08 | J27: =H27+I27 -> 1.9945088e+09 | L27: 45764 | N27: =J27-M27 -> 1.9945088e+09 | P27: =J27-M27-N27 -> 0
A28: 45680 | B28: 22/TAG/GMT/I/2025 | C28: PT. Srijasa Brika Perkasa | E28: 9310000 | F28: 7680750 | H28: =SUM(D28:G28) -> 16990750 | I28: =H28*0.11 -> 1868982.5 | J28: =H28+I28 -> 18859732 | L28: 45714 | N28: =J28-M28 -> 18859732 | P28: =J28-M28-N28 -> 0
A29: 45685 | B29: 23/TAG/GMT/I/2025 | C29: PT. Gemilang MitraAbadi Sejahtera | E29: 1300000 | H29: =SUM(D29:G29) -> 1300000 | I29: =H29*0.11 -> 143000 | J29: =H29+I29 -> 1443000 | L29: 45695 | N29: =J29-M29 -> 1443000 | P29: =J29-M29-N29 -> 0
A30: 45687 | B30: 24/TAGGMT/I/2025 | C30: PT. Shinagawa Refratech Perkasa | E30: 100000000 | H30: =SUM(D30:G30) -> 100000000 | I30: =H30*0.11 -> 11000000 | J30: =H30+I30 -> 111000000 | L30: 45723 | N30: =J30-M30 -> 111000000 | P30: =J30-M30-N30 -> 0
A31: 45685 | B31: 25/TAG/GMT/I/2025 | C31: PT. Karya Andesta | F31: 17100000 | H31: =SUM(D31:G31) -> 17100000 | I31: =H31*0.11 -> 1881000 | J31: =H31+I31 -> 18981000 | L31: 45771 | N31: =J31-M31 -> 18981000 | P31: =J31-M31-N31 -> 0
H32: =SUM(D32:G32) -> 0 | I32: =H32*0.11 -> 0 | J32: =H32+I32 -> 0 | N32: =J32-M32 -> 0 | P32: =J32-M32-N32 -> 0
H33: =SUM(D33:G33) -> 0 | I33: =H33*0.11 -> 0 | J33: =H33+I33 -> 0 | N33: 0 | P33: =J33-M33-N33 -> 0
A34: Total | D34: =SUM(D7:D33) -> 1106775000 | E34: =SUM(E7:E33) -> 160937500 | F34: =SUM(F7:F33) -> 2716640034 | G34: =SUM(G7:G33) -> 0 | H34: =SUM(H7:H33) -> 3984352534 | I34: =SUM(I7:I33) -> 4.3827878e+08 | J34: =SUM(J7:J33) -> 4.4226313e+09 | M34: =SUM(M7:M33) -> 22045833 | N34: =SUM(N7:N33) -> 4.265583e+09 | P34: =SUM(P7:P33) -> 1.350025e+08
H35: 3799492534
F36: PM→→→→→→→→→→ | H36: =H34-H35 -> 184860000
L38: =J24+J27+J28 -> 2.0214513e+09
L39: =+'INV FEBRUARI'!J14 -> 4112550
L40: =SUM(L38:L39) -> 2.0255638e+09
L41: 17000000
L42: =SUM(L40:L41) -> 2.0425638e+09

Sheet INV FEBRUARI
A1: Piutang GMT Februari 2025
A4: PPN
A5: Tanggal | B5: No. Invoice | C5: Customer | D5: Keterangan | L5: Tgl Pembayaran | M5: PPH 2% | N5: Nilai Pembayaran | P5: Saldo AR
D6: Jasa | E6: Anchor | F6: Material | G6: Sewa Alat | H6: Total | I6: PPN | J6: Grand Total
A7: 45692 | B7: 26/TAG/GMT/II/2025 | C7: PT. Harmoni Energy Indonesia | F7: 9810000 | H7: =SUM(D7:G7) -> 9810000 | I7: =H7*0.11 -> 1079100 | J7: =H7+I7 -> 10889100 | L7: 45681 | N7: =J7-M7 -> 10889100 | P7: =J7-M7-N7 -> 0
A8: 45693 | B8: 27/TAG/GMT/II/2025 | C8: PT. Daiki Aluminium Industry Indonesia | F8: 6687500 | H8: =SUM(D8:G8) -> 6687500 | I8: =H8*0.11 -> 735625 | J8: =H8+I8 -> 7423125 | L8: 45730 | N8: =J8-M8 -> 7423125 | P8: =J8-M8-N8 -> 0 | Q8: 203788875
A9: 45693 | B9: 28/TAG/GMT/II/2025 | C9: PT. Daiki Aluminium Industry Indonesia | F9: 30500000 | H9: =SUM(D9:G9) -> 30500000 | I9: =H9*0.11 -> 3355000 | J9: =H9+I9 -> 33855000 | L9: 45730 | M9: 2000 | N9: =J9-M9 -> 33853000 | P9: =J9-M9-N9 -> 0 | Q9: =P8+P9+P10+P11+P16 -> 0
A10: 45694 | B10: 29/TAG/GMT/II/2025 | C10: PT. Daiki Aluminium Industry Indonesia | D10: 42250000 | H10: =SUM(D10:G10) -> 42250000 | I10: =H10*0.11 -> 4647500 | J10: =H10+I10 -> 46897500 | L10: 45730 | M10: =D10*0.02 -> 845000 | N10: =J10-M10 -> 46052500 | P10: =J10-M10-N10 -> 0 | Q10: =Q8-Q9 -> 203788875
A11: 45694 | B11: 30/TAG/GMT/II/2025 | C11: PT. Daiki Aluminium Industry Indonesia | D11: 5875000 | H11: =SUM(D11:G11) -> 5875000 | I11: =H11*0.11 -> 646250 | J11: =H11+I11 -> 6521250 | L11: 45730 | M11: =D11*0.02 -> 117500 | N11: =J11-M11 -> 6403750 | P11: =J11-M11-N11 -> 0
A12: 45694 | B12: 31/TAG/GMT/II/2025 | C12: PT. Srijasa Brika Perkasa | F12: 56875000 | H12: =SUM(D12:G12) -> 56875000 | I12: =H12*0.11 -> 6256250 | J12: =H12+I12 -> 63131250 | L12: 45714 | M12: =D12*0.02 -> 0 | N12: =J12-M12 -> 63131250 | P12: =J12-M12-N12 -> 0
A13: 45695 | B13: 32/TAG/GMT/II/2025 | C13: PT. Refratech Mandala Perkasa | E13: 15000000 | H13: =SUM(D13:G13) -> 15000000 | I13: =H13*0.11 -> 1650000 | J13: =H13+I13 -> 16650000 | L13: 45730 | N13: =J13-M13 -> 16650000 | P13: =J13-M13-N13 -> 0
A14: 45695 | B14: 33/TAG/GMT/II/2025 | C14: PT. Shinagawa Refratech Perkasa | E14: 3705000 | H14: =SUM(D14:G14) -> 3705000 | I14: =H14*0.11 -> 407550 | J14: =H14+I14 -> 4112550 | L14: 45730 | M14: 2000 | N14: =J14-M14 -> 4110550 | P14: =J14-M14-N14 -> 0 | Q14: =P14+P19 -> 0
A15: 45693 | B15: 34/TAG/GMT/II/2025 | C15: PT. Srijasa Brika Perkasa | F15: 56875000 | H15: =SUM(D15:G15) -> 56875000 | I15: =H15*0.11 -> 6256250 | J15: =H15+I15 -> 63131250 | L15: 45714 | N15: =J15-M15 -> 63131250 | P15: =J15-M15-N15 -> 0
A16: 45698 | B16: 35/TAG/GMT/II/2025 | C16: PT. Daiki Aluminium Industry Indonesia | F16: 99150000 | H16: =SUM(D16:G16) -> 99150000 | I16: =H16*0.11 -> 10906500 | J16: =H16+I16 -> 110056500 | L16: 45730 | N16: =J16-M16 -> 110056500 | P16: =J16-M16-N16 -> 0
A17: 45699 | B17: 36/TAG/GMT/II/2025 | C17: PT. Eagle Industry Indonesia | F17: 35625000 | H17: =SUM(D17:G17) -> 35625000 | I17: =H17*0.11 -> 3918750 | J17: =H17+I17 -> 39543750 | L17: 45742 | N17: =J17-M17 -> 39543750 | P17: =J17-M17-N17 -> 0
A18: 45698 | B18: 37/TAG/GMT/II/2025 | C18: PT. Global Energy Solusindo | D18: =37050000 -> 37050000 | F18: 20056025 | H18: =SUM(D18:G18) -> 57106025 | I18: =H18*0.11 -> 6281662.8 | J18: =H18+I18 -> 63387688 | L18: 45699 | M18: =D18*0.02 -> 741000 | N18: =J18-M18 -> 62646688 | P18: =J18-M18-N18 -> 0
A19: 45699 | B19: 38/TAG/GMT/II/2025 | C19: PT. Shinagawa Refratech Perkasa | E19: 16463000 | H19: =SUM(D19:G19) -> 16463000 | I19: =H19*0.11 -> 1810930 | J19: =H19+I19 -> 18273930 | L19: 45730 | N19: =J19-M19 -> 18273930 | P19: =J19-M19-N19 -> 0
A20: 45691 | B20: 39/TAG/GMT/II/2025 | C20: PT. Bumi Alam Segar | D20: 55000000 | H20: =SUM(D20:G20) -> 55000000 | I20: =H20*0.11 -> 6050000 | J20: =H20+I20 -> 61050000 | L20: 45736 | M20: =D20*0.02 -> 1100000 | N20: =J20-M20 -> 59950000 | P20: =J20-M20-N20 -> 0
A21: 45700 | B21: 40/TAG/GMT/II/2025 | C21: PT. Bumi Alam Segar | F21: 2090000 | H21: =SUM(D21:G21) -> 2090000 | I21: =H21*0.11 -> 229900 | J21: =H21+I21 -> 2319900 | L21: 45736 | N21: =J21-M21 -> 2319900 | P21: =J21-M21-N21 -> 0
A22: 45701 | B22: 41/TAG/GMT/II/2025 | C22: PT. Karya Andesta | G22: 272100000 | H22: =SUM(D22:G22) -> 272100000 | I22: =H22*0.11 -> 29931000 | J22: =H22+I22 -> 302031000 | L22: 45771 | N22: =J22-M22 -> 302031000 | P22: =J22-M22-N22 -> 0
A23: 45701 | B23: 42/TAG/GMT/II/2025 | C23: PT. Daiki Aluminium Industry Indonesia | F23: 59825000 | H23: =SUM(D23:G23) -> 59825000 | I23: =H23*0.11 -> 6580750 | J23: =H23+I23 -> 66405750 | L23: 45743 | N23: =J23-M23 -> 66405750 | P23: =J23-M23-N23 -> 0
A24: 45702 | B24: 43/TAG/GMT/II/2025 | C24: PT. Pantarhei Cahaya Indonesia | E24: 99450000 | H24: =SUM(D24:G24) -> 99450000 | I24: =H24*0.11 -> 10939500 | J24: =H24+I24 -> 110389500 | L24: 45793 | N24: =J24-M24 -> 110389500 | P24: =J24-M24-N24 -> 0
A25: 45712 | B25: 44/TAG/GMT/II/2025 | C25: PT. Kaltim Prima Coal | F25: 26125000 | H25: =SUM(D25:G25) -> 26125000 | I25: =H25*0.11 -> 2873750 | J25: =H25+I25 -> 28998750 | N25: 0 | P25: =J25-M25-N25 -> 28998750
A26: 45712 | B26: 45/TAG/GMT/II/2025 | C26: PT. Kaltim Prima Coal | F26: 34200000 | H26: =SUM(D26:G26) -> 34200000 | I26: =H26*0.11 -> 3762000 | J26: =H26+I26 -> 37962000 | N26: 0 | P26: =J26-M26-N26 -> 37962000
A27: 45709 | B27: 46/TAG/GMT/II/2025 | C27: PT. Daiki Aluminium Industry Indonesia | F27: 3350000 | H27: =SUM(D27:G27) -> 3350000 | I27: =H27*0.11 -> 368500 | J27: =H27+I27 -> 3718500 | L27: 45743 | M27: 2000 | N27: =J27-M27 -> 3716500 | P27: =J27-M27-N27 -> 0
A28: 45712 | B28: 47/TAG/GMT/II/2025 | C28: PT. Pantarhei Cahaya Indonesia | E28: 50400000 | H28: =SUM(D28:G28) -> 50400000 | I28: =H28*0.11 -> 5544000 | J28: =H28+I28 -> 55944000 | L28: 45784 | M28: =D28*0.02 -> 0 | N28: =J28-M28 -> 55944000 | P28: =J28-M28-N28 -> 0
A29: 45714 | B29: 48/TAG/GMT/II/2025 | C29: PT. Daiki Aluminium Industry Indonesia | D29: 103400000 | H29: =SUM(D29:G29) -> 103400000 | I29: =H29*0.11 -> 11374000 | J29: =H29+I29 -> 114774000 | L29: 45743 | M29: =D29*0.02 -> 2068000 | N29: =J29-M29 -> 112706000 | P29: =J29-M29-N29 -> 0
A30: 45715 | B30: 49/TAG/GMT/II/2025 | C30: PT. Gemilang Mitra Abadi Sejahtera | E30: 19041993 | H30: =SUM(D30:G30) -> 19041993 | I30: =H30*0.11 -> 2094619.2 | J30: =H30+I30 -> 21136612 | L30: 45729 | N30: =J30-M30 -> 21136612 | P30: =J30-M30-N30 -> 0
H31: =SUM(D31:G31) -> 0 | I31: =H31*0.11 -> 0 | J31: =H31+I31 -> 0 | M31: =D31*0.02 -> 0 | N31: =J31-M31 -> 0 | P31: =J31-M31-N31 -> 0
A32: Total | D32: =SUM(D7:D31) -> 243575000 | E32: =SUM(E7:E31) -> 204059993 | F32: =SUM(F7:F31) -> 441168525 | G32: =SUM(G7:G31) -> 272100000 | H32: =SUM(H7:H31) -> 1160903518 | I32: =SUM(I7:I31) -> 1.2769939e+08 | J32: =SUM(J7:J31) -> 1.2886029e+09 | M32: =SUM(M7:M31) -> 4877500 | N32: =SUM(N7:N31) -> 1.2167647e+09 | P32: =SUM(P7:P31) -> 66960750 | U32: =SUM(U7:U31) -> 0
U33: =M32-U32 -> 4877500
J35: =J27+J29 -> 118492500
J36: =J23 -> 66405750 | N36: =N23+N27+N29 -> 182828250
J37: =SUM(J35:J36) -> 184898250

Sheet INV MARET
A1: Piutang GMT Maret 2025
A2: PPN
A3: Tanggal | B3: No. Invoice | C3: Customer | D3: Keterangan | L3: Tgl Pembayaran | M3: Potongan PPH 2% | N3: Nilai Pembayaran | P3: Saldo AR
D4: Jasa | E4: Anchor | F4: Material | G4: Sewa Alat | H4: Total | I4: PPN | J4: Grand Total
A5: 45720 | B5: 50/TAG/GMT/III/2025 | C5: PT. Daiki Aluminium Industry Indonesia | D5: 250000000 | H5: =SUM(D5:G5) -> 250000000 | I5: =H5*0.11 -> 27500000 | J5: =H5+I5 -> 277500000 | L5: 45762 | M5: =D5*0.02 -> 5000000 | N5: =J5-M5 -> 272500000 | P5: =J5-M5-N5 -> 0
A6: 45722 | B6: 51/TAG/GMT/III/2025 | C6: PT. Harindo Jaya Nusantara | D6: =34950000-1230000 -> 33720000 | F6: =45378000-1598000 -> 43780000 | H6: =SUM(D6:G6) -> 77500000 | I6: =H6*0.11 -> 8525000 | J6: =H6+I6 -> 86025000 | L6: 45726 | N6: =J6-M6 -> 86025000 | P6: =J6-M6-N6 -> 0
A7: 45723 | B7: 52/TAG/GMT/III/2025 | C7: PT. Shinagawa Refratech Perkasa | E7: 9536000 | H7: =SUM(D7:G7) -> 9536000 | I7: =H7*0.11 -> 1048960 | J7: =H7+I7 -> 10584960 | L7: 45764 | N7: =J7-M7 -> 10584960 | P7: =J7-M7-N7 -> 0
A8: 45727 | B8: 53/TAG/GMT/III/2025 | C8: PT. Daiki Aluminium Industry Indonesia | F8: 8500000 | H8: =SUM(D8:G8) -> 8500000 | I8: =H8*0.11 -> 935000 | J8: =H8+I8 -> 9435000 | L8: 45762 | M8: 2000 | N8: =J8-M8 -> 9433000 | P8: =J8-M8-N8 -> 0
A9: 45729 | B9: 54/TAG/GMT/III/2025 | C9: PT. Shinagawa Refratech Perkasa | E9: 120000000 | H9: =SUM(D9:G9) -> 120000000 | I9: =H9*0.11 -> 13200000 | J9: =H9+I9 -> 133200000 | L9: 45764 | N9: =J9-M9 -> 133200000 | P9: =J9-M9-N9 -> 0
A10: 45729 | B10: 55/TAG/GMT/III/2025 | C10: PT. Gemilang Mitra Abadi Sejahtera | E10: 6500000 | H10: =SUM(D10:G10) -> 6500000 | I10: =H10*0.11 -> 715000 | J10: =H10+I10 -> 7215000 | L10: 45735 | N10: =J10-M10 -> 7215000 | P10: =J10-M10-N10 -> 0
A11: 45730 | B11: 56/TAG/GMT/III/2025 | C11: PT. Shinagawa Refratech Perkasa | E11: 106127500 | H11: =SUM(D11:G11) -> 106127500 | I11: =H11*0.11 -> 11674025 | J11: =H11+I11 -> 117801525 | L11: 45764 | N11: =J11-M11 -> 117801525 | P11: =J11-M11-N11 -> 0
A12: 45733 | B12: 57/TAG/GMT/III/2025 | C12: CV. Nioto Karunia Mulya | F12: 11700000 | H12: =SUM(D12:G12) -> 11700000 | I12: =H12*0.11 -> 1287000 | J12: =H12+I12 -> 12987000 | L12: 45782 | N12: =J12-M12 -> 12987000 | P12: =J12-M12-N12 -> 0
A13: 45733 | B13: 58/TAG/GMT/III/2025 | C13: PT. Daiki Aluminium Industry Indonesia | F13: 58425000 | H13: =SUM(D13:G13) -> 58425000 | I13: =H13*0.11 -> 6426750 | J13: =H13+I13 -> 64851750 | L13: 45777 | N13: =J13-M13 -> 64851750 | P13: =J13-M13-N13 -> 0
A14: 45737 | B14: 59/TAG/GMT/III/2025 | C14: PT. Shinagawa Refratech Perkasa | E14: 1092500 | H14: =SUM(D14:G14) -> 1092500 | I14: =H14*0.11 -> 120175 | J14: =H14+I14 -> 1212675 | L14: 45772 | N14: =J14-M14 -> 1212675 | P14: =J14-M14-N14 -> 0
A15: 45740 | B15: 60/TAG/GMT/III/2025 | C15: PT. Gemilang Mitra Abadi Sejahtera | E15: 7800000 | H15: =SUM(D15:G15) -> 7800000 | I15: =H15*0.11 -> 858000 | J15: =H15+I15 -> 8658000 | L15: 45772 | N15: =J15-M15 -> 8658000 | P15: =J15-M15-N15 -> 0
A16: 45741 | B16: 61/TAG/GMT/III/2025 | C16: PT. Daiki Aluminium Industry Indonesia | F16: 65300000 | H16: =SUM(D16:G16) -> 65300000 | I16: =H16*0.11 -> 7183000 | J16: =H16+I16 -> 72483000 | L16: 45777 | N16: =J16-M16 -> 72483000 | P16: =J16-M16-N16 -> 0
A17: 45741 | B17: 62/TAG/GMT/III/2025 | C17: PT. Daiki Aluminium Industry Indonesia | F17: 142500000 | H17: =SUM(D17:G17) -> 142500000 | I17: =H17*0.11 -> 15675000 | J17: =H17+I17 -> 158175000 | L17: 45777 | N17: =J17-M17 -> 158175000 | P17: =J17-M17-N17 -> 0
A18: 45741 | B18: 63/TAG/GMT/III/2025 | C18: PT. Daiki Aluminium Industry Indonesia | F18: 630300000 | H18: =SUM(D18:G18) -> 630300000 | I18: =H18*0.11 -> 69333000 | J18: =H18+I18 -> 699633000 | L18: 45777 | N18: =J18-M18 -> 699633000 | P18: =J18-M18-N18 -> 0
A19: 45741 | B19: 64/TAG/GMT/III/2025 | C19: PT. Daiki Aluminium Industry Indonesia | F19: 130600000 | H19: =SUM(D19:G19) -> 130600000 | I19: =H19*0.11 -> 14366000 | J19: =H19+I19 -> 144966000 | L19: 45777 | N19: =J19-M19 -> 144966000 | P19: =J19-M19-N19 -> 0
A20: 45741 | B20: 65/TAG/GMT/III/2025 | C20: PT. Daiki Aluminium Industry Indonesia | F20: 496900000 | H20: =SUM(D20:G20) -> 496900000 | I20: =H20*0.11 -> 54659000 | J20: =H20+I20 -> 551559000 | L20: 45777 | N20: =J20-M20 -> 551559000 | P20: =J20-M20-N20 -> 0
A21: 45741 | B21: 66/TAG/GMT/III/2025 | C21: PT. Daiki Aluminium Industry Indonesia | F21: 359000000 | H21: =SUM(D21:G21) -> 359000000 | I21: =H21*0.11 -> 39490000 | J21: =H21+I21 -> 398490000 | L21: 45777 | N21: =J21-M21 -> 398490000 | P21: =J21-M21-N21 -> 0
A22: 45741 | B22: 67/TAG/GMT/III/2025 | C22: PT. Daiki Aluminium Industry Indonesia | F22: 677000000 | H22: =SUM(D22:G22) -> 677000000 | I22: =H22*0.11 -> 74470000 | J22: =H22+I22 -> 751470000 | L22: 45777 | N22: =J22-M22 -> 751470000 | P22: =J22-M22-N22 -> 0
A23: 45741 | B23: 68/TAG/GMT/III/2025 | C23: PT. Daiki Aluminium Industry Indonesia | F23: 171000000 | H23: =SUM(D23:G23) -> 171000000 | I23: =H23*0.11 -> 18810000 | J23: =H23+I23 -> 189810000 | L23: 45777 | N23: =J23-M23 -> 189810000 | P23: =J23-M23-N23 -> 0
A24: 45741 | B24: 69/TAG/GMT/III/2025 | C24: PT. Daiki Aluminium Industry Indonesia | F24: 141450000 | H24: =SUM(D24:G24) -> 141450000 | I24: =H24*0.11 -> 15559500 | J24: =H24+I24 -> 157009500 | L24: 45777 | N24: =J24-M24 -> 157009500 | P24: =J24-M24-N24 -> 0
H25: =SUM(D25:G25) -> 0 | I25: =H25*0.11 -> 0 | J25: =H25+I25 -> 0 | M25: =D25*0.02 -> 0 | P25: =J25-M25-N25 -> 0
C26: Total | D26: =SUM(D5:D25) -> 283720000 | E26: =SUM(E5:E25) -> 251056000 | F26: =SUM(F5:F25) -> 2936455000 | G26: =SUM(G5:G25) -> 0 | H26: =SUM(H5:H25) -> 3471231000 | I26: =SUM(I5:I25) -> 381835410 | J26: =SUM(J5:J25) -> 3853066410 | M26: =SUM(M5:M25) -> 5002000 | N26: =SUM(N5:N25) -> 3848064410 | P26: =SUM(P5:P25) -> 0
J29: =J16+J17+J18+J19+J20+J21+J22+J23+J24 -> 3123595500
J30: =J13+J29 -> 3188447250
H33: 261584485
H34: =J7+J9+J11 -> 261586485

Sheet INV APRIL
A1: Piutang GMT April 2025
A3: PPN
A4: Tanggal | B4: No. Invoice | C4: Customer | D4: Keterangan | L4: Tgl Pembayaran | M4: Potongan PPH 2% | N4: Nilai Pembayaran | P4: Saldo AR
D5: Jasa | E5: Anchor | F5: Material | G5: Sewa Alat | H5: Total | I5: PPN | J5: Grand Total
A6: 45757 | B6: 70/TAG/GMT/IV/2025 | C6: PT. Daiki Aluminium Industry Indonesia | G6: 151500000 | H6: =SUM(D6:G6) -> 151500000 | I6: =H6*0.11 -> 16665000 | J6: =H6+I6 -> 168165000 | L6: 45792 | M6: =G6*0.02 -> 3030000 | N6: =J6-M6 -> 165135000 | P6: =J6-M6-N6 -> 0
A7: 45757 | B7: 71/TAG/GMT/IV/2025 | C7: PT. Daiki Aluminium Industry Indonesia | D7: 79500000 | H7: =SUM(D7:G7) -> 79500000 | I7: =H7*0.11 -> 8745000 | J7: =H7+I7 -> 88245000 | L7: 45792 | M7: =D7*0.02 -> 1590000 | N7: =J7-M7 -> 86655000 | P7: =J7-M7-N7 -> 0
A8: 45757 | B8: 72/TAG/GMT/IV/2025 | C8: PT. Daiki Aluminium Industry Indonesia | D8: 192700000 | H8: =SUM(D8:G8) -> 192700000 | I8: =H8*0.11 -> 21197000 | J8: =H8+I8 -> 213897000 | L8: 45792 | M8: =D8*0.02 -> 3854000 | N8: =J8-M8 -> 210043000 | P8: =J8-M8-N8 -> 0
A9: 45757 | B9: 73/TAG/GMT/IV/2025 | C9: PT. Daiki Aluminium Industry Indonesia | D9: 155900000 | H9: =SUM(D9:G9) -> 155900000 | I9: =H9*0.11 -> 17149000 | J9: =H9+I9 -> 173049000 | L9: 45792 | M9: =D9*0.02 -> 3118000 | N9: =J9-M9 -> 169931000 | P9: =J9-M9-N9 -> 0
A10: 45757 | B10: 74/TAG/GMT/IV/2025 | C10: PT. Daiki Aluminium Industry Indonesia | G10: 67000000 | H10: =SUM(D10:G10) -> 67000000 | I10: =H10*0.11 -> 7370000 | J10: =H10+I10 -> 74370000 | L10: 45792 | M10: =G10*0.02 -> 1340000 | N10: =J10-M10 -> 73030000 | P10: =J10-M10-N10 -> 0 | Q10: =N6+N7+N8+N9+N10+N11+N12+N13+N14+N15+N16+N17+N18+N19+N20+N21+N22+N23+N24 -> 2.3238904e+09
A11: 45757 | B11: 75/TAG/GMT/IV/2025 | C11: PT. Daiki Aluminium Industry Indonesia | D11: 96400000 | H11: =SUM(D11:G11) -> 96400000 | I11: =H11*0.11 -> 10604000 | J11: =H11+I11 -> 107004000 | L11: 45792 | M11: =D11*0.02 -> 1928000 | N11: =J11-M11 -> 105076000 | P11: =J11-M11-N11 -> 0
A12: 45757 | B12: 76/TAG/GMT/IV/2025 | C12: PT. Daiki Aluminium Industry Indonesia | D12: 78600000 | H12: =SUM(D12:G12) -> 78600000 | I12: =H12*0.11 -> 8646000 | J12: =H12+I12 -> 87246000 | L12: 45792 | M12: =D12*0.02 -> 1572000 | N12: =J12-M12 -> 85674000 | P12: =J12-M12-N12 -> 0
A13: 45757 | B13: 77/TAG/GMT/IV/2025 | C13: PT. Daiki Aluminium Industry Indonesia | G13: 67000000 | H13: =SUM(D13:G13) -> 67000000 | I13: =H13*0.11 -> 7370000 | J13: =H13+I13 -> 74370000 | L13: 45792 | M13: =G13*0.02 -> 1340000 | N13: =J13-M13 -> 73030000 | P13: =J13-M13-N13 -> 0
A14: 45757 | B14: 78/TAG/GMT/IV/2025 | C14: PT. Daiki Aluminium Industry Indonesia | D14: 166800000 | H14: =SUM(D14:G14) -> 166800000 | I14: =H14*0.11 -> 18348000 | J14: =H14+I14 -> 185148000 | L14: 45792 | M14: =D14*0.02 -> 3336000 | N14: =J14-M14 -> 181812000 | P14: =J14-M14-N14 -> 0
A15: 45757 | B15: 79/TAG/GMT/IV/2025 | C15: PT. Daiki Aluminium Industry Indonesia | D15: 91800000 | H15: =SUM(D15:G15) -> 91800000 | I15: =H15*0.11 -> 10098000 | J15: =H15+I15 -> 101898000 | L15: 45792 | M15: =D15*0.02 -> 1836000 | N15: =J15-M15 -> 100062000 | P15: =J15-M15-N15 -> 0
A16: 45757 | B16: 80/TAG/GMT/IV/2025 | C16: PT. Daiki Aluminium Industry Indonesia | D16: 80700000 | H16: =SUM(D16:G16) -> 80700000 | I16: =H16*0.11 -> 8877000 | J16: =H16+I16 -> 89577000 | L16: 45792 | M16: =D16*0.02 -> 1614000 | N16: =J16-M16 -> 87963000 | P16: =J16-M16-N16 -> 0
A17: 45756 | B17: 81/TAG/GMT/IV/2025 | C17: PT. Common Wealth Steel Indonesia | F17: 43050000 | H17: =SUM(D17:G17) -> 43050000 | I17: =H17*0.11 -> 4735500 | J17: =H17+I17 -> 47785500 | L17: 45786 | N17: =J17-M17 -> 47785500 | P17: =J17-M17-N17 -> 0
A18: 45757 | B18: 82/TAG/GMT/IV/2025 | C18: PT. Daiki Aluminium Industry Indonesia | D18: 52000000 | H18: =SUM(D18:G18) -> 52000000 | I18: =H18*0.11 -> 5720000 | J18: =H18+I18 -> 57720000 | L18: 45792 | M18: =D18*0.02 -> 1040000 | N18: =J18-M18 -> 56680000 | P18: =J18-M18-N18 -> 0
A19: 45757 | B19: 83/TAG/GMT/IV/2025 | C19: PT. Daiki Aluminium Industry Indonesia | F19: 94898750 | H19: =SUM(D19:G19) -> 94898750 | I19: =H19*0.11 -> 10438862 | J19: =H19+I19 -> 1.0533761e+08 | L19: 45792 | N19: =J19-M19 -> 1.0533761e+08 | P19: =J19-M19-N19 -> 0 | Q19: =SUM(P6:P16) -> 0
A20: 45757 | B20: 84/TAG/GMT/IV/2025 | C20: PT. Daiki Aluminium Industry Indonesia | F20: 108800000 | H20: =SUM(D20:G20) -> 108800000 | I20: =H20*0.11 -> 11968000 | J20: =H20+I20 -> 120768000 | L20: 45792 | N20: =J20-M20 -> 120768000 | P20: =J20-M20-N20 -> 0 | Q20: =SUM(P18:P24) -> 0
A21: 45757 | B21: 85/TAG/GMT/IV/2025 | C21: PT. Daiki Aluminium Industry Indonesia | F21: 571435000 | H21: =SUM(D21:G21) -> 571435000 | I21: =H21*0.11 -> 62857850 | J21: =H21+I21 -> 634292850 | L21: 45792 | N21: =J21-M21 -> 634292850 | P21: =J21-M21-N21 -> 0 | Q21: =SUM(Q19:Q20) -> 0
A22: 45757 | B22: 86/TAG/GMT/IV/2025 | C22: PT. Daiki Aluminium Industry Indonesia | D22: 12125000 | H22: =SUM(D22:G22) -> 12125000 | I22: =H22*0.11 -> 1333750 | J22: =H22+I22 -> 13458750 | L22: 45792 | M22: =D22*0.02 -> 242500 | N22: =J22-M22 -> 13216250 | P22: =J22-M22-N22 -> 0
A23: 45757 | B23: 87/TAG/GMT/IV/2025 | C23: PT. Daiki Aluminium Industry Indonesia | F23: 1265000 | H23: =SUM(D23:G23) -> 1265000 | I23: =H23*0.11 -> 139150 | J23: =H23+I23 -> 1404150 | L23: 45792 | N23: =J23-M23 -> 1404150 | P23: =J23-M23-N23 -> 0 | Q23: 2.2739239e+09
A24: 45757 | B24: 88/TAG/GMT/IV/2025 | C24: PT. Daiki Aluminium Industry Indonesia | D24: 5500000 | H24: =SUM(D24:G24) -> 5500000 | I24: =H24*0.11 -> 605000 | J24: =H24+I24 -> 6105000 | L24: 45792 | M24: =D24*0.02 -> 110000 | N24: =J24-M24 -> 5995000 | P24: =J24-M24-N24 -> 0 | Q24: =Q10-Q23 -> 49966500
A25: 45757 | B25: 89/TAG/GMT/IV/2025 | C25: PT. Gemilang Mitra Abadi Sejahtera | E25: 1550000 | H25: =SUM(D25:G25) -> 1550000 | I25: =H25*0.11 -> 170500 | J25: =H25+I25 -> 1720500 | L25: 45818 | N25: =J25-M25 -> 1720500 | P25: =J25-M25-N25 -> 0
A26: 45757 | B26: 90/TAG/GMT/IV/2025 | C26: PT. Shinagawa Maju Persada | E26: 18390000 | H26: =SUM(D26:G26) -> 18390000 | I26: =H26*0.11 -> 2022900 | J26: =H26+I26 -> 20412900 | L26: 45792 | N26: =J26-M26 -> 20412900 | P26: =J26-M26-N26 -> 0
A27: 45762 | B27: 91/TAG/GMT/IV/2025 | C27: PT. Shinagawa Refratech Perkasa | F27: 1900000 | H27: =SUM(D27:G27) -> 1900000 | I27: =H27*0.11 -> 209000 | J27: =H27+I27 -> 2109000 | L27: 45793 | N27: =J27-M27 -> 2109000 | P27: =J27-M27-N27 -> 0
A28: 45762 | B28: 92/TAG/GMT/IV/2025 | C28: PT. Shinagawa Refratech Perkasa | E28: 16444000 | H28: =SUM(D28:G28) -> 16444000 | I28: =H28*0.11 -> 1808840 | J28: =H28+I28 -> 18252840 | L28: 45793 | N28: =J28-M28 -> 18252840 | P28: =J28-M28-N28 -> 0
A29: 45762 | B29: 93/TAG/GMT/IV/2025 | C29: PT. Shinagawa Refratech Perkasa | E29: 5751500 | H29: =SUM(D29:G29) -> 5751500 | I29: =H29*0.11 -> 632665 | J29: =H29+I29 -> 6384165 | L29: 45793 | N29: =J29-M29 -> 6384165 | P29: =J29-M29-N29 -> 0
A30: 45762 | B30: 94/TAG/GMT/IV/2025 | C30: PT. Daiki Aluminium Industry Indonesia | F30: 125800000 | H30: =SUM(D30:G30) -> 125800000 | I30: =H30*0.11 -> 13838000 | J30: =H30+I30 -> 139638000 | L30: 45805 | N30: =J30-M30 -> 139638000 | P30: =J30-M30-N30 -> 0
A31: 45762 | B31: 95/TAG/GMT/IV/2025 | C31: PT. Shinagawa Refratech Perkasa | D31: 135000000 | H31: =SUM(D31:G31) -> 135000000 | I31: =H31*0.11 -> 14850000 | J31: =H31+I31 -> 149850000 | L31: 45793 | M31: =(D31*0.02)+2000 -> 2702000 | N31: =J31-M31 -> 147148000 | P31: =J31-M31-N31 -> 0
A32: 45762 | B32: 96/TAG/GMT/IV/2025 | C32: PT. Aqpa Indonesia | F32: 5150000 | H32: =SUM(D32:G32) -> 5150000 | I32: =H32*0.11 -> 566500 | J32: =H32+I32 -> 5716500 | L32: 45758 | N32: =J32-M32 -> 5716500 | P32: =J32-M32-N32 -> 0
A33: 45762 | B33: 97/TAG/GMT/IV/2025 | C33: PT. Pantarhei Cahaya Indonesia | E33: 33150000 | H33: =SUM(D33:G33) -> 33150000 | I33: =H33*0.11 -> 3646500 | J33: =H33+I33 -> 36796500 | L33: 45838 | N33: =J33-M33 -> 36796500 | P33: =J33-M33-N33 -> 0
A34: 45762 | B34: 98/TAG/GMT/IV/2025 | C34: PT. Eagle Industry Indonesia | F34: 35625000 | H34: =SUM(D34:G34) -> 35625000 | I34: =H34*0.11 -> 3918750 | J34: =H34+I34 -> 39543750 | L34: 45805 | N34: =J34-M34 -> 39543750 | P34: =J34-M34-N34 -> 0
A35: 45762 | B35: 99/TAG/GMT/IV/2025 | C35: PT. Prakarsa Alam Segar | D35: 40125000 | H35: =SUM(D35:G35) -> 40125000 | I35: =H35*0.11 -> 4413750 | J35: =H35+I35 -> 44538750 | L35: 45812 | M35: =D35*0.02 -> 802500 | N35: =J35-M35 -> 43736250 | P35: =J35-M35-N35 -> 0
A36: 45762 | B36: 100/TAG/GMT/IV/2025 | C36: PT. Prakarsa Alam Segar | D36: 14500000 | H36: =SUM(D36:G36) -> 14500000 | I36: =H36*0.11 -> 1595000 | J36: =H36+I36 -> 16095000 | L36: 45812 | M36: =D36*0.02 -> 290000 | N36: =J36-M36 -> 15805000 | P36: =J36-M36-N36 -> 0
A37: 45764 | B37: 101/TAG/GMT/IV/2025 | C37: PT. Indoporlen | E37: 20300000 | H37: =SUM(D37:G37) -> 20300000 | I37: =H37*0.11 -> 2233000 | J37: =H37+I37 -> 22533000 | L37: 45791 | N37: =J37-M37 -> 22533000 | P37: =J37-M37-N37 -> 0
A38: 45763 | B38: 102/TAG/GMT/IV/2025 | C38: CV. Nioto Karunia Sukses | F38: 17550000 | H38: =SUM(D38:G38) -> 17550000 | I38: =H38*0.11 -> 1930500 | J38: =H38+I38 -> 19480500 | L38: 45791 | N38: =J38-M38 -> 19480500 | P38: =J38-M38-N38 -> 0
A39: 45763 | B39: 103/TAG/GMT/IV/2025 | C39: PT. Aqpa Indonesia | D39: 4250000 | H39: =SUM(D39:G39) -> 4250000 | I39: =H39*0.11 -> 467500 | J39: =H39+I39 -> 4717500 | L39: 45758 | M39: =D39*0.02 -> 85000 | N39: =J39-M39 -> 4632500 | P39: =J39-M39-N39 -> 0
A40: 45763 | B40: 104/TAG/GMT/IV/2025 | C40: PT. Vardhana Inti Pratama | E40: 18914000 | H40: =SUM(D40:G40) -> 18914000 | I40: =H40*0.11 -> 2080540 | J40: =H40+I40 -> 20994540 | L40: 45763 | N40: =J40-M40 -> 20994540 | P40: =J40-M40-N40 -> 0
A41: 45764 | B41: 105/TAG/GMT/IV/2025 | C41: PT. Pantarhei Cahaya Indonesia | E41: 153000000 | H41: =SUM(D41:G41) -> 153000000 | I41: =H41*0.11 -> 16830000 | J41: =H41+I41 -> 169830000 | L41: 45838 | N41: =J41-M41 -> 169830000 | P41: =J41-M41-N41 -> 0
...

Sheet INV MEI
A1: Piutang GMT Mei 2025
A3: PPN
A4: Tanggal | B4: No. Invoice | C4: Customer | D4: Keterangan | L4: Tgl Pembayaran | M4: Potongan PPH 2% | N4: Nilai Pembayaran | P4: Saldo AR
D5: Jasa | E5: Anchor | F5: Material | G5: Sewa Alat | H5: Total | I5: PPN | J5: Grand Total
A6: 45782 | B6: 115/TAG/GMT/V/2025 | C6: PT. Indopower International | F6: 8677500 | H6: =SUM(D6:G6) -> 8677500 | I6: =H6*0.11 -> 954525 | J6: =H6+I6 -> 9632025 | L6: 45782 | N6: =J6-M6 -> 9632025 | P6: =J6-N6 -> 0
A7: 45782 | B7: 116/TAG/GMT/V/2025 | C7: PT. Daiki Aluminium Industry Indonesia | D7: 74000000 | H7: =SUM(D7:G7) -> 74000000 | I7: =H7*0.11 -> 8140000 | J7: =H7+I7 -> 82140000 | L7: 45824 | M7: =(D7*0.02)+2000 -> 1482000 | N7: =J7-M7 -> 80658000 | P7: =J7-M7-N7 -> 0
A8: 45786 | B8: 117/TAG/GMT/V/2025 | C8: PT. Gemilang Mitraabadi Sejahtera | E8: 9100000 | H8: =SUM(D8:G8) -> 9100000 | I8: =H8*0.11 -> 1001000 | J8: =H8+I8 -> 10101000 | L8: 45818 | N8: =J8-M8 -> 10101000 | P8: =J8-N8-M8 -> 0
A9: 45790 | B9: 118/TAG/GMT/V/2025 | C9: PT. Halco Tehnik | F9: 51200370 | H9: =SUM(D9:G9) -> 51200370 | I9: =H9*0.11 -> 5632040.7 | J9: =H9+I9 -> 56832411 | L9: 45827 | N9: =J9-M9 -> 56832411 | P9: =J9-N9-M9 -> 0
A10: 45790 | B10: 119/TAG/GMT/V/2025 | C10: PT. Pantarhei Cahaya Indonesia | E10: 29925000 | H10: =SUM(D10:G10) -> 29925000 | I10: =H10*0.11 -> 3291750 | J10: =H10+I10 -> 33216750 | L10: 45868 | N10: =J10-M10 -> 33216750 | P10: =J10-N10-M10 -> 0
A11: 45790 | B11: 120/TAG/GMT/V/2025 | C11: PT. Eagle Industry Indonesia | F11: 14250000 | H11: =SUM(D11:G11) -> 14250000 | I11: =H11*0.11 -> 1567500 | J11: =H11+I11 -> 15817500 | L11: 45824 | N11: =J11-M11 -> 15817500 | P11: =J11-N11-M11 -> 0
A12: 45790 | B12: 121/TAG/GMT/V/2025 | C12: PT. Shinagawa Refratech Perkasa | D12: 377000000 | H12: =SUM(D12:G12) -> 377000000 | I12: =H12*0.11 -> 41470000 | J12: =H12+I12 -> 418470000 | L12: 45870 | M12: =D12*0.02 -> 7540000 | N12: =J12-M12 -> 410930000 | P12: =J12-N12-M12 -> 0
A13: 45790 | B13: 122/TAG/GMT/V/2025 | C13: PT. Shinagawa Refratech Perkasa | D13: 187103350 | F13: =427000000-187103350 -> 239896650 | H13: =SUM(D13:G13) -> 427000000 | I13: =H13*0.11 -> 46970000 | J13: =H13+I13 -> 473970000 | L13: 45870 | M13: =D13*0.02 -> 3742067 | N13: =J13-M13 -> 470227933 | P13: =J13-N13-M13 -> 0
A14: 45790 | B14: 123/TAG/GMT/V/2025 | C14: PT. Shinagawa Refratech Perkasa | D14: 126000000 | H14: =SUM(D14:G14) -> 126000000 | I14: =H14*0.11 -> 13860000 | J14: =H14+I14 -> 139860000 | L14: 45870 | M14: =D14*0.02 -> 2520000 | N14: =J14-M14 -> 137340000 | P14: =J14-N14-M14 -> 0
A15: 45790 | B15: 124/TAG/GMT/V/2025 | C15: PT. Shinagawa Refratech Perkasa | D15: 233000000 | H15: =SUM(D15:G15) -> 233000000 | I15: =H15*0.11 -> 25630000 | J15: =H15+I15 -> 258630000 | L15: 45870 | M15: =D15*0.02 -> 4660000 | N15: =J15-M15 -> 253970000 | P15: =J15-N15-M15 -> 0
A16: 45793 | B16: 125/TAG/GMT/V/2025 | C16: PT. Pantarhei Cahaya Indonesia | E16: 137700000 | H16: =SUM(D16:G16) -> 137700000 | I16: =H16*0.11 -> 15147000 | J16: =H16+I16 -> 152847000 | L16: 45868 | N16: =J16-M16 -> 152847000 | P16: =J16-N16-M16 -> 0
A17: 45798 | B17: 126/TAG/GMT/V/2025 | C17: PT. Rastekindo Cipta Global | F17: 1000000 | H17: =SUM(D17:G17) -> 1000000 | I17: =H17*0.11 -> 110000 | J17: =H17+I17 -> 1110000 | L17: 45797 | N17: =J17-M17 -> 1110000 | P17: =J17-N17-M17 -> 0
A18: 45798 | B18: 127/TAG/GMT/V/2025 | C18: PT. Daiki Aluminium Industry Indonesia | D18: 14350000 | H18: =SUM(D18:G18) -> 14350000 | I18: =H18*0.11 -> 1578500 | J18: =H18+I18 -> 15928500 | L18: 45838 | M18: =D18*0.02 -> 287000 | N18: =J18-M18 -> 15641500 | P18: =J18-N18-M18 -> 0
A19: 45798 | B19: 128/TAG/GMT/V/2025 | C19: PT. Daiki Aluminium Industry Indonesia | F19: 8500000 | H19: =SUM(D19:G19) -> 8500000 | I19: =H19*0.11 -> 935000 | J19: =H19+I19 -> 9435000 | L19: 45838 | M19: 4000 | N19: =J19-M19 -> 9431000 | P19: =J19-M19-N19 -> 0
A20: 45800 | B20: 129/TAG/GMT/V/2025 | C20: PT. Menara Bukit Lubukkeli | E20: 58386850 | H20: =SUM(D20:G20) -> 58386850 | I20: =H20*0.11 -> 6422553.5 | J20: =H20+I20 -> 64809404 | L20: 45813 | N20: =J20-M20 -> 64809404 | P20: =J20-N20 -> 0
N21: 0 | P21: =J21-N21 -> 0
H22: =SUM(D22:G22) -> 0 | I22: =H22*0.11 -> 0 | J22: =H22+I22 -> 0 | M22: =D22*0.02 -> 0 | N22: 0 | P22: =J22-M22-N22 -> 0
C23: Total | D23: =SUM(D6:D22) -> 1011453350 | E23: =SUM(E6:E22) -> 235111850 | F23: =SUM(F6:F22) -> 323524520 | G23: =SUM(G6:G22) -> 0 | H23: =SUM(H6:H22) -> 1570089720 | I23: =SUM(I6:I22) -> 1.7270987e+08 | J23: =SUM(J6:J22) -> 1.7427996e+09 | M23: =SUM(M7:M22) -> 20235067 | N23: =SUM(N7:N22) -> 1.7129325e+09 | P23: =SUM(P6:P22) -> 0
P27: =P12+P13+P14+P15 -> 0

Sheet INV JUNI
A1: Piutang GMT Juni 2025
A3: PPN
A4: Tanggal | B4: No. Invoice | C4: Customer | D4: Keterangan | L4: Tgl Pembayaran | M4: Potongan PPH 2% | N4: Nilai Pembayaran | P4: Saldo AR
D5: Jasa | E5: Anchor | F5: Material | G5: Sewa Alat | H5: Total | I5: PPN | J5: Grand Total
A6: 45811 | B6: 130/TAG/GMT/V/2025 | C6: PT. Prakarsa Alam Segar | D6: 40125000 | H6: =SUM(D6:G6) -> 40125000 | I6: =H6*0.11 -> 4413750 | J6: =H6+I6 -> 44538750 | L6: 45852 | M6: =(D6*0.02)+3000 -> 805500 | N6: =J6-M6 -> 43733250 | P6: =J6-M6-N6 -> 0
A7: 45811 | B7: 131/TAG/GMT/VI/2025 | C7: PT. Daiki Aluminium Industry Indonesia | F7: 2530000 | H7: =SUM(D7:G7) -> 2530000 | I7: =H7*0.11 -> 278300 | J7: =H7+I7 -> 2808300 | L7: 45853 | N7: =J7-M7 -> 2808300 | P7: =J7-M7-N7 -> 0
A8: 45812 | B8: 132/TAG/GMT/VI/2025 | C8: PT. Daiki Aluminium Industry Indonesia | F8: 1250000 | H8: =SUM(D8:G8) -> 1250000 | I8: =H8*0.11 -> 137500 | J8: =H8+I8 -> 1387500 | L8: 45853 | M8: 2000 | N8: =J8-M8 -> 1385500 | P8: =J8-M8-N8 -> 0
A9: 45813 | B9: 133/TAG/GMT/VI/2025 | C9: PT. Refractorindo Graha Dinamika | F9: 49600000 | H9: =SUM(D9:G9) -> 49600000 | I9: =H9*0.11 -> 5456000 | J9: =H9+I9 -> 55056000 | L9: 45842 | N9: =J9-M9 -> 55056000 | P9: =J9-M9-N9 -> 0
A10: 45818 | B10: 134/TAG/GMT/VI/2025 | C10: PT. Eagle Industry Indonesia | F10: 14250000 | H10: =SUM(D10:G10) -> 14250000 | I10: =H10*0.11 -> 1567500 | J10: =H10+I10 -> 15817500 | L10: 45853 | N10: =J10-M10 -> 15817500 | P10: =J10-M10-N10 -> 0
A11: 45820 | B11: 135/TAG/GMT/VI/2025 | C11: PT. Pantarhei Cahaya Indonesia | E11: 8316000 | H11: =SUM(D11:G11) -> 8316000 | I11: =H11*0.11 -> 914760 | J11: =H11+I11 -> 9230760 | L11: 45896 | N11: =J11-M11 -> 9230760 | P11: =J11-M11-N11 -> 0
A12: 45820 | B12: 136/TAG/GMT/VI/2025 | C12: PT. Pantarhei Cahaya Indonesia | E12: 28350000 | H12: =SUM(D12:G12) -> 28350000 | I12: =H12*0.11 -> 3118500 | J12: =H12+I12 -> 31468500 | L12: 45896 | N12: =J12-M12 -> 31468500 | P12: =J12-M12-N12 -> 0
A13: 45824 | B13: 137/TAG/GMT/VI/2025 | C13: PT. Shinagawa Refratech Perkasa | E13: 27108500 | H13: =SUM(D13:G13) -> 27108500 | I13: =H13*0.11 -> 2981935 | J13: =H13+I13 -> 30090435 | L13: 45867 | M13: 2000 | N13: =J13-M13 -> 30088435 | P13: =J13-M13-N13 -> 0
A14: 45825 | B14: 138/TAG/GMT/VI/2025 | C14: PT. Bumi Alam Segar | F14: 1567500 | H14: =SUM(D14:G14) -> 1567500 | I14: =H14*0.11 -> 172425 | J14: =H14+I14 -> 1739925 | L14: 45862 | N14: =J14-M14 -> 1739925 | P14: =J14-M14-N14 -> 0
A15: 45824 | B15: 139/TAG/GMT/VI/2025 | C15: PT. Shinagawa Refratech Perkasa | E15: 22100000 | H15: =SUM(D15:G15) -> 22100000 | I15: =H15*0.11 -> 2431000 | J15: =H15+I15 -> 24531000 | L15: 45867 | N15: =J15-M15 -> 24531000 | P15: =J15-M15-N15 -> 0
A16: 45825 | B16: 140/TAG/GMT/VI/2025 | C16: PT. Shinagawa Refratech Perkasa | E16: 7069000 | H16: =SUM(D16:G16) -> 7069000 | I16: =H16*0.11 -> 777590 | J16: =H16+I16 -> 7846590 | L16: 45867 | N16: =J16-M16 -> 7846590 | P16: =J16-M16-N16 -> 0 | Q16: =P16+P17 -> 0
A17: 45827 | B17: 141/TAG/GMT/VI/2025 | C17: PT. Shinagawa Refratech Perkasa | E17: 11500000 | H17: =SUM(D17:G17) -> 11500000 | I17: =H17*0.11 -> 1265000 | J17: =H17+I17 -> 12765000 | L17: 45867 | N17: =J17-M17 -> 12765000 | P17: =J17-M17-N17 -> 0
A18: 45828 | B18: 142/TAG/GMT/VI/2025 | C18: PT. Pantarhei Cahaya Indonesia | E18: 39000000 | H18: =SUM(D18:G18) -> 39000000 | I18: =H18*0.11 -> 4290000 | J18: =H18+I18 -> 43290000 | L18: 45896 | N18: =J18-M18 -> 43290000 | P18: =J18-M18-N18 -> 0
A19: 45834 | B19: 143/TAG/GMT/VI/2025 | C19: PT. Commonwealth Steel Indonesia | F19: 41025000 | H19: =SUM(D19:G19) -> 41025000 | I19: =H19*0.11 -> 4512750 | J19: =H19+I19 -> 45537750 | L19: 45866 | N19: =J19-M19 -> 45537750 | P19: =J19-M19-N19 -> 0
A20: 45834 | B20: 144/TAG/GMT/VI/2025 | C20: PT. Indo Bharat Rayon | F20: 48700800 | H20: =SUM(D20:G20) -> 48700800 | I20: =H20*0.11 -> 5357088 | J20: =H20+I20 -> 54057888 | L20: 45869 | N20: =J20-M20 -> 54057888 | P20: =J20-M20-N20 -> 0
A21: 45838 | B21: 145/TAG/GMT/VI/2025 | C21: PT. Refratech Mandala Perkasa | E21: 3480000 | H21: =SUM(D21:G21) -> 3480000 | I21: =H21*0.11 -> 382800 | J21: =H21+I21 -> 3862800 | L21: 45867 | N21: =J21-M21 -> 3862800 | P21: =J21-M21-N21 -> 0
H22: =SUM(D22:G22) -> 0 | I22: =H22*0.11 -> 0 | J22: =H22+I22 -> 0 | N22: =J22-M22 -> 0 | P22: =J22-M22-N22 -> 0
H23: =SUM(D23:G23) -> 0 | I23: =H23*0.11 -> 0 | J23: =H23+I23 -> 0 | N23: 0 | P23: =J23-M23-N23 -> 0
C24: Total | D24: =SUM(D6:D23) -> 40125000 | E24: =SUM(E6:E23) -> 146923500 | F24: =SUM(F6:F23) -> 158923300 | G24: =SUM(G6:G23) -> 0 | H24: =SUM(H6:H23) -> 345971800 | I24: =SUM(I6:I23) -> 38056898 | J24: =SUM(J6:J23) -> 384028698 | M24: =SUM(M9:M23) -> 2000 | N24: =SUM(N9:N23) -> 335292148 | P24: =SUM(P6:P23) -> 0
I28: 8.0593
I29: 5.4467 | J29: 3999917
E30: PM | F30: 1760000 | J30: 7499980
F31: 56261 | J31: =SUM(J29:J30) -> 11499897 | N31: =N6+N21 -> 47596050
F32: 2435400 | J32: =J31/1771000 -> 6.4934483
F33: 82500 | J33: =I28+J32 -> 14.552748
F34: 679250
F35: 49550
F36: 1155000
F37: 38847
F38: 42811
F39: 275000
F40: 3292207
F41: 192500
F42: 8493375
F43: 4015000
F44: 16060000
...

Sheet INV JULI
A1: Piutang GMT Juli 2025
A3: PPN
A4: Tanggal | B4: No. Invoice | C4: Customer | D4: Keterangan | L4: Tgl Pembayaran | M4: Potongan PPH 2% | N4: Nilai Pembayaran | P4: Saldo AR
D5: Jasa | E5: Anchor | F5: Material | G5: Sewa Alat | H5: Total | I5: PPN | J5: Grand Total
A6: 45839 | B6: 146/TAG/GMT/VII/2025 | C6: PT. Halco Tehnik | D6: 80262000 | H6: =SUM(D6:G6) -> 80262000 | I6: =H6*0.11 -> 8828820 | J6: =H6+I6 -> 89090820 | L6: 45880 | M6: =D6*0.02 -> 1605240 | N6: =J6-M6 -> 87485580 | P6: =J6-M6-N6 -> 0
A7: 45842 | B7: 147/TAG/GMT/VII/2025 | C7: PT. Pantarhei Cahaya Indonesia | F7: 36100000 | H7: =SUM(D7:G7) -> 36100000 | I7: =H7*0.11 -> 3971000 | J7: =H7+I7 -> 40071000 | L7: 45926 | N7: =J7-M7 -> 40071000 | P7: =J7-M7-N7 -> 0
A8: 45842 | B8: 148/TAG/GMT/VII/2025 | C8: CV. Nioto Karunia Mulya | F8: 11700000 | H8: =SUM(D8:G8) -> 11700000 | I8: =H8*0.11 -> 1287000 | J8: =H8+I8 -> 12987000 | L8: 45911 | N8: =J8-M8 -> 12987000 | P8: =J8-M8-N8 -> 0
A9: 45842 | B9: 149/TAG/GMT/VII/2025 | C9: PT. Pantarhei Cahaya Indonesia | E9: 28350000 | H9: =SUM(D9:G9) -> 28350000 | I9: =H9*0.11 -> 3118500 | J9: =H9+I9 -> 31468500 | L9: 45926 | N9: =J9-M9 -> 31468500 | P9: =J9-M9-N9 -> 0
A10: 45842 | B10: 150/TAG/GMT/VII/2025 | C10: PT. Vardhana Inti Pratama | E10: 174787750 | H10: =SUM(D10:G10) -> 174787750 | I10: =H10*0.11 -> 19226652 | J10: =H10+I10 -> 1.940144e+08 | L10: 45842 | N10: 194014403 | P10: 0
A11: 45847 | B11: 151/TAG/GMT/VII/2025 | C11: PT. Prabha Padma Pertiwi | F11: 1100000 | H11: =SUM(D11:G11) -> 1100000 | I11: =H11*0.11 -> 121000 | J11: =H11+I11 -> 1221000 | L11: 45847 | N11: =J11-M11 -> 1221000 | P11: =J11-M11-N11 -> 0
A12: 45847 | B12: 152/TAG/GMT/VII/2025 | C12: PT. Eagle Industry Indonesia | F12: 14205000 | H12: =SUM(D12:G12) -> 14205000 | I12: =H12*0.11 -> 1562550 | J12: =H12+I12 -> 15767550 | L12: 45884 | N12: =J12-M12 -> 15767550 | P12: =J12-M12-N12 -> 0
A13: 45847 | B13: 153/TAG/GMT/VII/2025 | C13: PT. Prabha Padma Pertiwi | F13: 550000 | H13: =SUM(D13:G13) -> 550000 | I13: =H13*0.11 -> 60500 | J13: =H13+I13 -> 610500 | L13: 45847 | N13: =J13-M13 -> 610500 | P13: =J13-M13-N13 -> 0
A14: 45842 | B14: 154/TAG/GMT/VII/2025 | C14: PT. Vardhana Inti Pratama | E14: 174787750 | H14: =SUM(D14:G14) -> 174787750 | I14: =H14*0.11 -> 19226652 | J14: =H14+I14 -> 1.940144e+08 | L14: 45856 | N14: =J14-M14 -> 1.940144e+08 | P14: =J14-M14-N14 -> 0
A15: 45856 | B15: 155/TAG/GMT/VII/2025 | C15: PT. Pantarhei Cahaya Indonesia | E15: 30600000 | H15: =SUM(D15:G15) -> 30600000 | I15: =H15*0.11 -> 3366000 | J15: =H15+I15 -> 33966000 | L15: 45926 | N15: =J15-M15 -> 33966000 | P15: =J15-M15-N15 -> 0
A16: 45855 | B16: 156/TAG/GMT/VII/2025 | C16: PT. Indopower International | F16: 4628000 | H16: =SUM(D16:G16) -> 4628000 | I16: =H16*0.11 -> 509080 | J16: =H16+I16 -> 5137080 | L16: 45855 | N16: =J16-M16 -> 5137080 | P16: =J16-M16-N16 -> 0
A17: 45859 | B17: 157/TAG/GMT/VII/2025 | C17: PT. Vardhana Inti Pratama | E17: 9457000 | H17: =SUM(D17:G17) -> 9457000 | I17: =H17*0.11 -> 1040270 | J17: =H17+I17 -> 10497270 | L17: 45859 | N17: =J17-M17 -> 10497270 | P17: =J17-M17-N17 -> 0
A18: 45859 | B18: 158/TAG/GMT/VII/2025 | C18: PT. Vardhana Inti Pratama | E18: 9457000 | H18: =SUM(D18:G18) -> 9457000 | I18: =H18*0.11 -> 1040270 | J18: =H18+I18 -> 10497270 | L18: 45925 | N18: =J18-M18 -> 10497270 | P18: =J18-M18-N18 -> 0
A19: 45862 | B19: 159/TAG/GMT/VII/2025 | C19: PT. Daiki Aluminium Industry Indonesia | F19: 44000000 | H19: =SUM(D19:G19) -> 44000000 | I19: =H19*0.11 -> 4840000 | J19: =H19+I19 -> 48840000 | L19: 45898 | M19: 1000 | N19: =J19-M19 -> 48839000 | P19: =J19-M19-N19 -> 0
A20: 45862 | B20: 160/TAG/GMT/VII/2025 | C20: PT. Daiki Aluminium Industry Indonesia | F20: 587400000 | H20: =SUM(D20:G20) -> 587400000 | I20: =H20*0.11 -> 64614000 | J20: =H20+I20 -> 652014000 | L20: 45898 | N20: =J20-M20 -> 652014000 | P20: =J20-M20-N20 -> 0
A21: 45866 | B21: 161/TAG/GMT/VII/2025 | C21: PT. Shinagawa Refratech Perkasa | E21: 15115000 | H21: =SUM(D21:G21) -> 15115000 | I21: =H21*0.11 -> 1662650 | J21: =H21+I21 -> 16777650 | L21: 45898 | M21: 2000 | N21: =J21-M21 -> 16775650 | P21: =J21-M21-N21 -> 0
A22: 45866 | B22: 162/TAG/GMT/VII/2025 | C22: PT. Shinagawa Refratech Perkasa | E22: 963000 | H22: =SUM(D22:G22) -> 963000 | I22: =H22*0.11 -> 105930 | J22: =H22+I22 -> 1068930 | L22: 45898 | N22: =J22-M22 -> 1068930 | P22: =J22-M22-N22 -> 0
A23: 45866 | B23: 163/TAG/GMT/VII/2025 | C23: PT. Shinagawa Refratech Perkasa | E23: 18150000 | H23: =SUM(D23:G23) -> 18150000 | I23: =H23*0.11 -> 1996500 | J23: =H23+I23 -> 20146500 | L23: 45898 | N23: =J23-M23 -> 20146500 | P23: =J23-M23-N23 -> 0
A24: 45861 | B24: 169/TAG/GMT/VII/2025 | C24: PT. Common Wealth Steel Indonesia | F24: 25300000 | H24: =SUM(D24:G24) -> 25300000 | I24: =H24*0.11 -> 2783000 | J24: =H24+I24 -> 28083000 | L24: 45910 | N24: =J24-M24 -> 28083000 | P24: =J24-M24-N24 -> 0
P25: =J25-M25-N25 -> 0
P26: =J26-M26-N26 -> 0
H27: =SUM(D27:G27) -> 0 | I27: 0 | J27: =H27+I27 -> 0 | N27: 0 | P27: =J27-M27-N27 -> 0
H28: =SUM(D28:G28) -> 0 | I28: =H28*0.11 -> 0 | J28: =H28+I28 -> 0 | N28: =J28-M28 -> 0 | P28: =J28-M28-N28 -> 0
H29: =SUM(D29:G29) -> 0 | I29: =H29*0.11 -> 0 | J29: =H29+I29 -> 0 | M29: 0 | N29: =J29-M29 -> 0 | P29: =J29-M29-N29 -> 0
H30: =SUM(D30:G30) -> 0 | I30: =H30*0.11 -> 0 | J30: =H30+I30 -> 0 | M30: =D30*0.02 -> 0 | N30: =J30-M30 -> 0 | P30: =J30-M30-N30 -> 0 | U30: =M30 -> 0
C31: Total | D31: =SUM(D6:D30) -> 80262000 | E31: =SUM(E6:E30) -> 461667500 | F31: =SUM(F6:F30) -> 724983000 | G31: =SUM(G6:G30) -> 0 | H31: =SUM(H6:H30) -> 1266912500 | I31: =SUM(I6:I30) -> 139360375 | J31: =SUM(J6:J30) -> 1406272875 | M31: =SUM(M6:M30) -> 1608240 | N31: =SUM(N6:N30) -> 1.4046646e+09 | P31: =SUM(P6:P30) -> 0 | R31: =SUM(R6:R30) -> 0 | S31: =SUM(S6:S30) -> 0 | U31: =SUM(U6:U30) -> 0
U32: =M31-U31 -> 1608240
I33: 8985803
H34: 36300000
H35: 2461800
H36: 1980000
H37: 2435400
H38: 187000 | J38: =J19+J20 -> 700854000
H39: 2200000 | J39: =J21+J22+J23 -> 37993080
H40: 935000
H41: 1760000
...

Sheet INV AGUSTUS
A1: Piutang GMT Agustus 2025
J2: =J10+J11+J14+J24+J31 -> 278739315
A3: PPN
A5: Tanggal | B5: No. Invoice | C5: Customer | D5: Keterangan | L5: Tgl Pembayaran | M5: Potongan PPH 2% | N5: Nilai Pembayaran | P5: Saldo AR
D6: Jasa | E6: Anchor | F6: Material | G6: Sewa Alat | H6: Total | I6: PPN | J6: Grand Total
A7: 45870 | B7: 164/TAG/GMT/VII/2025 | C7: PT. Sinergi Bangun Utama | E7: 56887000 | H7: =SUM(D7:G7) -> 56887000 | I7: =H7*0.11 -> 6257570 | J7: =H7+I7 -> 63144570 | L7: 45877 | N7: =J7-M7 -> 63144570 | P7: =J7-M7-N7 -> 0
A8: 45870 | B8: 165/TAG/GMT/VII/2025 | C8: PT. Sinergi Bangun Utama | E8: 4408575 | H8: =SUM(D8:G8) -> 4408575 | I8: =H8*0.11 -> 484943.25 | J8: =H8+I8 -> 4893518.2 | L8: 45877 | N8: =J8-M8 -> 4893518.2
A9: 45870 | B9: 166/TAG/GMT/VIII/2025 | C9: PT. Lingga Makmur Elektrika | F9: 1200000 | H9: =SUM(D9:G9) -> 1200000 | I9: =H9*0.11 -> 132000 | J9: =SUM(H9:I9) -> 1332000 | L9: 45870 | N9: =J9-M9 -> 1332000
A10: 45870 | B10: 167/TAG/GMT/VIII/2025 | C10: PT. Vardhana Inti Pratama | E10: 5200000 | H10: =SUM(D10:G10) -> 5200000 | I10: =H10*0.11 -> 572000 | J10: =SUM(H10:I10) -> 5772000 | L10: 45870 | N10: =J10-M10 -> 5772000 | P10: =J10-M10-N10 -> 0
A11: 45870 | B11: 168/TAG/GMT/VIII/2025 | C11: PT. Vardhana Inti Pratama | E11: 5200000 | H11: =SUM(D11:G11) -> 5200000 | I11: =H11*0.11 -> 572000 | J11: =SUM(H11:I11) -> 5772000 | L11: 45978 | N11: =J11-M11 -> 5772000 | P11: =J11-M11-N11 -> 0
A12: 45874 | B12: 170/TAG/GMT/VIII/2025 | C12: PT. Raja Voltama Electric | E12: 114025031 | H12: =SUM(D12:G12) -> 114025031 | I12: =H12*0.11 -> 12542753 | J12: =SUM(H12:I12) -> 1.2656778e+08 | L12: 45874 | N12: =J12-M12 -> 1.2656778e+08 | P12: =J12-M12-N12 -> 0
A13: 45874 | B13: 171/TAG/GMT/VIII/2025 | C13: PT. Vardhana Inti Pratama | E13: 19605250 | H13: =SUM(D13:G13) -> 19605250 | I13: =H13*0.11 -> 2156577.5 | J13: =SUM(H13:I13) -> 21761828 | L13: 45874 | N13: =J13-M13 -> 21761828 | P13: =J13-M13-N13 -> 0
A14: 45874 | B14: 172/TAG/GMT/VIII/2025 | C14: PT. Vardhana Inti Pratama | E14: 19605250 | H14: =SUM(D14:G14) -> 19605250 | I14: =H14*0.11 -> 2156577.5 | J14: =SUM(H14:I14) -> 21761828 | L14: 45978 | N14: =J14-M14 -> 21761828 | P14: =J14-M14-N14 -> 0
A15: 45874 | B15: 173/TAG/GMT/VIII/2025 | C15: PT. Pantarhei Cahaya Indonesia | E15: 84150000 | H15: =SUM(D15:G15) -> 84150000 | I15: =H15*0.11 -> 9256500 | J15: =SUM(H15:I15) -> 93406500 | L15: 45986 | N15: =J15-M15 -> 93406500 | P15: =J15-M15-N15 -> 0
A16: 45875 | B16: 174/TAG/GMT/VIII/2025 | C16: PT. Daiki Aluminium Industry Indonesia | F16: 64600000 | H16: =SUM(D16:G16) -> 64600000 | I16: =H16*0.11 -> 7106000 | J16: =SUM(H16:I16) -> 71706000 | L16: 45915 | N16: =J16-M16 -> 71706000 | P16: =J16-M16-N16 -> 0
A17: 45875 | B17: 175/TAG/GMT/VIII/2025 | C17: PT. Daiki Aluminium Industry Indonesia | F17: 29400000 | H17: =SUM(D17:G17) -> 29400000 | I17: =H17*0.11 -> 3234000 | J17: =SUM(H17:I17) -> 32634000 | L17: 45915 | M17: 2900 | N17: =J17-M17 -> 32631100 | P17: =J17-M17-N17 -> 0
A18: 45877 | B18: 176/TAG/GMT/VIII/2025 | C18: PT. Daiki Aluminium Industry Indonesia | D18: 180900000 | H18: =SUM(D18:G18) -> 180900000 | I18: =H18*0.11 -> 19899000 | J18: =SUM(H18:I18) -> 200799000 | L18: 45915 | M18: =D18*0.02 -> 3618000 | N18: =J18-M18 -> 197181000 | P18: =J18-M18-N18 -> 0
A19: 45877 | B19: 177/TAG/GMT/VIII/2025 | C19: PT. Daiki Aluminium Industry Indonesia | D19: 56700000 | H19: =SUM(D19:G19) -> 56700000 | I19: =H19*0.11 -> 6237000 | J19: =SUM(H19:I19) -> 62937000 | L19: 45915 | M19: =D19*0.02 -> 1134000 | N19: =J19-M19 -> 61803000 | P19: =J19-M19-N19 -> 0
A20: 45875 | B20: 178/TAG/GMT/VIII/2025 | C20: PT. Prabha Padma Pertiwi | F20: 1800000 | H20: =SUM(D20:G20) -> 1800000 | I20: =H20*0.11 -> 198000 | J20: =SUM(H20:I20) -> 1998000 | L20: 45875 | N20: =J20-M20 -> 1998000 | P20: =J20-M20-N20 -> 0
A21: 45876 | B21: 179/TAG/GMT/VIII/2025 | C21: PT. Ihi Power Service Indonesia | F21: 314338500 | H21: =SUM(D21:G21) -> 314338500 | I21: =H21*0.11 -> 34577235 | J21: =SUM(H21:I21) -> 348915735 | N21: 0 | P21: =J21-M21-N21 -> 348915735
A22: 45877 | B22: 180/TAG/GMT/VIII/2025 | C22: PT. Sriwijaya Alam Segar | F22: 1905000 | H22: =SUM(D22:G22) -> 1905000 | I22: =H22*0.11 -> 209550 | J22: =SUM(H22:I22) -> 2114550 | L22: 45911 | N22: =J22-M22 -> 2114550 | P22: =J22-M22-N22 -> 0
A23: 45877 | B23: 181/TAG/GMT/VIII/2025 | C23: PT. Daiki Aluminium Industry Indonesia | F23: 25300000 | H23: =SUM(D23:G23) -> 25300000 | I23: =H23*0.11 -> 2783000 | J23: =SUM(H23:I23) -> 28083000 | L23: 45915 | N23: =J23-M23 -> 28083000 | P23: =J23-M23-N23 -> 0
A24: 45881 | B24: 182/TAG/GMT/VIII/2025 | C24: PT. Vardhana Inti Pratama | E24: 8811250 | H24: =SUM(D24:G24) -> 8811250 | I24: =H24*0.11 -> 969237.5 | J24: =SUM(H24:I24) -> 9780487.5 | L24: 45881 | N24: =J24-M24 -> 9780487.5 | P24: =J24-M24-N24 -> 0
A25: 45881 | B25: 183/TAG/GMT/VIII/2025 | C25: PT. Vardhana Inti Pratama | E25: 8811250 | H25: =SUM(D25:G25) -> 8811250 | I25: =H25*0.11 -> 969237.5 | J25: =SUM(H25:I25) -> 9780487.5 | L25: 45925 | N25: =J25-M25 -> 9780487.5 | P25: =J25-M25-N25 -> 0
A26: 45881 | B26: 184/TAG/GMT/VIII/2025 | C26: CV. Tiga Bintang Selaras | F26: 1364000 | H26: =SUM(D26:G26) -> 1364000 | I26: =H26*0.11 -> 150040 | J26: =SUM(H26:I26) -> 1514040 | L26: 45881 | N26: =J26-M26 -> 1514040 | P26: =J26-M26-N26 -> 0
A27: 45890 | B27: 185/TAG/GMT/VIII/2025 | C27: PT. Eagle Industry Indonesia | F27: 23750000 | H27: =SUM(D27:G27) -> 23750000 | I27: =H27*0.11 -> 2612500 | J27: =SUM(H27:I27) -> 26362500 | L27: 45930 | N27: =J27-M27 -> 26362500 | P27: =J27-M27-N27 -> 0
A28: 45890 | B28: 186/TAG/GMT/VIII/2025 | C28: PT. Daiki Aluminium Industry Indonesia | F28: 627910000 | H28: =SUM(D28:G28) -> 627910000 | I28: =H28*0.11 -> 69070100 | J28: =SUM(H28:I28) -> 696980100 | L28: 45930 | M28: 1000 | N28: =J28-M28 -> 696979100 | P28: =J28-M28-N28 -> 0
A29: 45894 | B29: 187/TAG/GMT/VIII/2025 | C29: CV. Nioto Karunia Mulya | F29: 11700000 | H29: =SUM(D29:G29) -> 11700000 | I29: =H29*0.11 -> 1287000 | J29: =SUM(H29:I29) -> 12987000 | N29: 0 | P29: =J29-M29-N29 -> 12987000
A30: 45896 | B30: 188/TAG/GMT/VIII/2025 | C30: PT. Refratech Mandala Perkasa | E30: 59520000 | H30: =SUM(D30:G30) -> 59520000 | I30: =H30*0.11 -> 6547200 | J30: =SUM(H30:I30) -> 66067200 | L30: 45933 | N30: =J30-M30 -> 66067200 | P30: =J30-M30-N30 -> 0
A31: 45894 | B31: 189/TAG/GMT/VIII/2025 | C31: PT. Ihi Power Service Indonesia | D31: 212300000 | H31: =SUM(D31:G31) -> 212300000 | I31: =H31*0.11 -> 23353000 | J31: =SUM(H31:I31) -> 235653000 | N31: 0 | P31: =J31-M31-N31 -> 235653000
A32: 45897 | B32: 190/TAG/GMT/VIII/2025 | C32: PT. Shinagawa Refratech Perkasa | E32: 408000 | H32: =SUM(D32:G32) -> 408000 | I32: =H32*0.11 -> 44880 | J32: =SUM(H32:I32) -> 452880 | L32: 45933 | N32: =J32-M32 -> 452880 | P32: =J32-M32-N32 -> 0
H33: =SUM(D33:G33) -> 0 | I33: =H33*0.11 -> 0 | J33: =SUM(H33:I33) -> 0 | M33: 0 | N33: =J33-M33 -> 0 | P33: =J33-M33-N33 -> 0
C34: Total | D34: =SUM(D7:D33) -> 449900000 | E34: =SUM(E7:E33) -> 386631606 | F34: =SUM(F7:F33) -> 1103267500 | G34: =SUM(G7:G33) -> 0 | H34: =SUM(H7:H33) -> 1939799106 | I34: =SUM(I7:I33) -> 2.133779e+08 | J34: =SUM(J7:J33) -> 2.153177e+09 | M34: =SUM(M7:M33) -> 4755900 | N34: =SUM(N7:N33) -> 1.5508654e+09 | P34: =SUM(P7:P33) -> 597555735 | S34: =SUM(S7:S33) -> 0 | U34: =SUM(U7:U33) -> 0
I36: 127183023
I37: =I34-I36 -> 86194879
H38: 3534300
H39: 41250000
H40: 4088700
H41: 1848000
H42: 154431
...

Sheet INV SEPTEMBER
A1: Piutang GMT September 2025
A3: PPN
A5: Tanggal | B5: No. Invoice | C5: Customer | D5: Keterangan | L5: Tgl Pembayaran | M5: Potongan PPH 2% | N5: Beban Admin | O5: Nilai Pembayaran | Q5: Saldo AR
D6: Jasa | E6: Anchor | F6: Material | G6: Sewa Alat | H6: Total | I6: PPN | J6: Grand Total
A7: 45902 | B7: 191/TAG/GMT/IX/2025 | C7: PT. Shinagawa Refratech Perkasa | E7: 7362000 | H7: =SUM(D7:G7) -> 7362000 | I7: =H7*0.11 -> 809820 | J7: =SUM(H7:I7) -> 8171820 | L7: 45933 | O7: =J7-M7-N7 -> 8171820 | Q7: =J7-M7-O7-N7 -> 0
A8: 45901 | B8: 192/TAG/GMT/IX/2025 | C8: PT. Raja Voltama Electric | E8: 20147500 | H8: =SUM(D8:G8) -> 20147500 | I8: =H8*0.11 -> 2216225 | J8: =SUM(H8:I8) -> 22363725 | L8: 45902 | O8: =J8-M8-N8 -> 22363725 | Q8: =J8-M8-O8-N8 -> 0
A9: 45901 | B9: 193/TAG/GMT/IX/2025 | C9: PT. Sinergi Bangun Utama | E9: 227548000 | H9: =SUM(D9:G9) -> 227548000 | I9: =H9*0.11 -> 25030280 | J9: =SUM(H9:I9) -> 252578280 | L9: 45946 | O9: =J9-M9-N9 -> 252578280 | Q9: =J9-M9-O9-N9 -> 0
A10: 45901 | B10: 194/TAG/GMT/IX/2025 | C10: PT. Sinergi Bangun Utama | E10: 17634300 | H10: =SUM(D10:G10) -> 17634300 | I10: =H10*0.11 -> 1939773 | J10: =SUM(H10:I10) -> 19574073 | L10: 45946 | O10: =J10-M10-N10 -> 19574073 | Q10: =J10-M10-O10-N10 -> 0
A11: 45903 | B11: 195/TAG/GMT/IX/2025 | C11: PT. Gemilang MitraAbadi Sejahtera | E11: 3900000 | H11: =SUM(D11:G11) -> 3900000 | I11: =H11*0.11 -> 429000 | J11: =SUM(H11:I11) -> 4329000 | L11: 45917 | O11: =J11-M11-N11 -> 4329000 | Q11: =J11-M11-O11-N11 -> 0
A12: 45903 | B12: 196/TAG/GMT/IX/2025 | C12: PT. Sriwijaya Alam Segar | F12: 3810000 | H12: =SUM(D12:G12) -> 3810000 | I12: =H12*0.11 -> 419100 | J12: =SUM(H12:I12) -> 4229100 | L12: 45938 | O12: =J12-M12-N12 -> 4229100 | Q12: =J12-M12-O12-N12 -> 0
A13: 45903 | B13: 197/TAG/GMT/IX/2025 | C13: PT. Exima Maju Perkasa | G13: 1200000 | H13: =SUM(D13:G13) -> 1200000 | I13: =H13*0.11 -> 132000 | J13: =SUM(H13:I13) -> 1332000 | L13: 45903 | O13: =J13-M13-N13 -> 1332000 | Q13: =J13-M13-O13-N13 -> 0
A14: 45908 | B14: 198/TAG/GMT/IX/2025 | C14: PT. Daiki Aluminium Industry Indonesia | F14: 37050000 | H14: =SUM(D14:G14) -> 37050000 | I14: =H14*0.11 -> 4075500 | J14: =SUM(H14:I14) -> 41125500 | L14: 45945 | O14: =J14-M14-N14 -> 41125500 | Q14: =J14-M14-O14-N14 -> 0
A15: 45908 | B15: 199/TAG/GMT/IX/2025 | C15: PT. Daiki Aluminium Industry Indonesia | F15: 10000000 | H15: =SUM(D15:G15) -> 10000000 | I15: =H15*0.11 -> 1100000 | J15: =SUM(H15:I15) -> 11100000 | L15: 45945 | O15: =J15-M15-N15 -> 11100000 | Q15: =J15-M15-O15-N15 -> 0
A16: 45904 | B16: 200/TAG/GMT/IX/2025 | C16: PT. Gemilang MitraAbadi Sejahtera | F16: 5100000 | H16: =SUM(D16:G16) -> 5100000 | I16: =H16*0.11 -> 561000 | J16: =SUM(H16:I16) -> 5661000 | L16: 45951 | O16: =J16-M16-N16 -> 5661000 | Q16: =J16-M16-O16-N16 -> 0
A17: 45913 | B17: 201/TAG/GMT/IX/2025 | C17: PT. Daiki Aluminium Industry Indonesia | D17: 165000000 | H17: =SUM(D17:G17) -> 165000000 | I17: =H17*0.11 -> 18150000 | J17: =SUM(H17:I17) -> 183150000 | L17: 45945 | M17: =D17*0.02 -> 3300000 | N17: 1000 | O17: =J17-M17-N17 -> 179849000 | Q17: =J17-M17-O17-N17 -> 0
